Workbook

Sheet Estado de Resultados
A1: =+Códigos!$A$1 -> LIBRO DIARIO OFICINA
A2: ESTADO DE RESULTADOS
A3: =+Códigos!$A$3 -> AÑO: | B3: =+Códigos!$B$3 -> 2025
C4: EDO de RDOS | D4: OFICINA 2020 | F4: Diferencias | G4: Revisión
B5: TOTAL INGRESOS | C5: =+C46 -> 791027153 | D5: =+'INGRESOS A CAJA'!G2 -> 634239583 | F5: =+C5-D5 -> 156787570 | G5: Dif OK/fras
B6: TOTALES EGRESOS | C6: =+C113 -> 629110853 | D6: =+'EGRESOS DE CAJA'!H2 -> 633732083 | F6: =+C6-D6 -> -4621230 | G6: Dif OK/IVA
G7: PROM MENSUAL
C8: Utilidad (+) o Pérdida (-) OPERACIONAL | D8: =+D46-D75 -> -161991104 | G8: =+D8/3 -> -53997035
C9: Utilidad (+) o Pérdida (-) GENERAL | D9: =+D46-D113 -> -412385813 | G9: =+D9/3 -> -1.3746194e+08
A11: CÓDIGO | B11: CONCEPTO | C11: OFICINA | D11: RESULTADOS
A14: INGRESOS A CAJA
A15: INGRESOS DE OPERACIÓN
B16: FACTURAS -GERMÁN TULIO FERNÁNDEZ FERNÁNDEZ- | C16: =+FACTURACIÓN!G98 -> 29603000 | D16: =+C16 -> 29603000
B17: OTROS COBROS -GERMÁN TULIO FERNÁNDEZ FERNÁNDEZ- | C17: =+FACTURACIÓN!G141 -> 0
B18: CUENTAS DE COBRO -DIEGO ALBERTO FERNÁNDEZ FERNÁNDEZ- | C18: =+FACTURACIÓN!G300 -> 121560000
B19: OTROS INGRESOS SIN FACTURACIÓN | C19: =+FACTURACIÓN!G322 -> 0 | D19: =+C19-FACTURACIÓN!J322 -> 0
B20: I V A | C20: =+FACTURACIÓN!H324 -> 5624570 | D20: =+C20 -> 5624570
B21: =_xlfn.XLOOKUP(A21,Códigos!$A$489:$A$522,Códigos!$B$489:$B$522,"Verificar",0) -> 0 | C21: =SUMIF('INGRESOS A CAJA'!$B$9:$B$4452,A21,'INGRESOS A CAJA'!$F$9:$F$4452) -> 0
A24: TOTAL INGRESOS DE OPERACIÓN | C24: =SUM(C16:C23) -> 156787570 | D24: =SUM(D16:D23) -> 35227570
A26: NO INGRESOS A CAJA
A28: A | B28: =_xlfn.XLOOKUP(A28,Códigos!$A$489:$A$522,Códigos!$B$489:$B$522,"Verificar",0) -> Recibido por: -FACTURAS -GTFF | C28: =SUMIF('INGRESOS A CAJA'!$B$9:$B$4452,A28,'INGRESOS A CAJA'!$F$9:$F$4452) -> 45615800
A29: B | B29: =_xlfn.XLOOKUP(A29,Códigos!$A$489:$A$522,Códigos!$B$489:$B$522,"Verificar",0) -> Recibido por: -Cuentas de cobro -GTFF | C29: =SUMIF('INGRESOS A CAJA'!$B$9:$B$4452,A29,'INGRESOS A CAJA'!$F$9:$F$4452) -> 0
A30: C | B30: =_xlfn.XLOOKUP(A30,Códigos!$A$489:$A$522,Códigos!$B$489:$B$522,"Verificar",0) -> Recibido por: -Cuentas de cobro -DAFF | C30: =SUMIF('INGRESOS A CAJA'!$B$9:$B$4452,A30,'INGRESOS A CAJA'!$F$9:$F$4452) -> 42540000
A31: D | B31: =_xlfn.XLOOKUP(A31,Códigos!$A$489:$A$522,Códigos!$B$489:$B$522,"Verificar",0) -> Recibido por: -Otros ingresos Sin Facturación | C31: =SUMIF('INGRESOS A CAJA'!$B$9:$B$4452,A31,'INGRESOS A CAJA'!$F$9:$F$4452) -> 0
A32: E | B32: =_xlfn.XLOOKUP(A32,Códigos!$A$489:$A$522,Códigos!$B$489:$B$522,"Verificar",0) -> Ingresos Recibidos de terceros para pagos | C32: =SUMIF('INGRESOS A CAJA'!$B$9:$B$4452,A32,'INGRESOS A CAJA'!$F$9:$F$4452) -> 1096000
A33: F | B33: =_xlfn.XLOOKUP(A33,Códigos!$A$489:$A$522,Códigos!$B$489:$B$522,"Verificar",0) -> Recibido por: -Cuentas por Cobrar | C33: =SUMIF('INGRESOS A CAJA'!$B$9:$B$4452,A33,'INGRESOS A CAJA'!$F$9:$F$4452) -> 10076800
A34: G | B34: =_xlfn.XLOOKUP(A34,Códigos!$A$489:$A$522,Códigos!$B$489:$B$522,"Verificar",0) -> Recibido por: -Abono a préstamos por Nómina de: | C34: =SUMIF('INGRESOS A CAJA'!$B$9:$B$4452,A34,'INGRESOS A CAJA'!$F$9:$F$4452) -> 1744200
A35: H | B35: =_xlfn.XLOOKUP(A35,Códigos!$A$489:$A$522,Códigos!$B$489:$B$522,"Verificar",0) -> Recibido por: -Abono a préstamos por Nómina de: | C35: =SUMIF('INGRESOS A CAJA'!$B$9:$B$4452,A35,'INGRESOS A CAJA'!$F$9:$F$4452) -> 0
A36: I | B36: =_xlfn.XLOOKUP(A36,Códigos!$A$489:$A$522,Códigos!$B$489:$B$522,"Verificar",0) -> -Retiros y Traslados de Bancos | C36: =SUMIF('INGRESOS A CAJA'!$B$9:$B$4452,A36,'INGRESOS A CAJA'!$F$9:$F$4452) -> 533166783
A37: J | B37: =_xlfn.XLOOKUP(A37,Códigos!$A$489:$A$522,Códigos!$B$489:$B$522,"Verificar",0) -> -Consignaciones pendientes de identificar | C37: =SUMIF('INGRESOS A CAJA'!$B$9:$B$4452,A37,'INGRESOS A CAJA'!$F$9:$F$4452) -> 0
A38: K | B38: =_xlfn.XLOOKUP(A38,Códigos!$A$489:$A$522,Códigos!$B$489:$B$522,"Verificar",0) -> Recibido por: -Préstamos a favor de la oficina | C38: =SUMIF('INGRESOS A CAJA'!$B$9:$B$4452,A38,'INGRESOS A CAJA'!$F$9:$F$4452) -> 0
A39: L | B39: =_xlfn.XLOOKUP(A39,Códigos!$A$489:$A$522,Códigos!$B$489:$B$522,"Verificar",0) -> Reembolsos y recuperaciones | C39: =SUMIF('INGRESOS A CAJA'!$B$9:$B$4452,A39,'INGRESOS A CAJA'!$F$9:$F$4452) -> 0
B40: RETENCIÓN EN LA FUENTE | C40: =SUMIF('INGRESOS A CAJA'!$B$9:$B$4452,A40,'INGRESOS A CAJA'!$F$9:$F$4452) -> 0 | D40: =-FACTURACIÓN!J324 -> -3256330
B41: =_xlfn.XLOOKUP(A41,Códigos!$A$489:$A$522,Códigos!$B$489:$B$522,"Verificar",0) -> 0 | C41: =SUMIF('INGRESOS A CAJA'!$B$9:$B$4452,A41,'INGRESOS A CAJA'!$F$9:$F$4452) -> 0
A44: TOTAL NO INGRESOS A CAJA | C44: =SUM(C28:C43) -> 634239583 | D44: =SUM(D28:D43) -> -3256330
A46: TOTAL INGRESOS A CAJA | C46: =+C24+C44 -> 791027153 | D46: =+D24+D44 -> 31971240 | F46: =+D46-D75 -> -161991104 | G46: Utilidad (+) o Pérdida (-) OPERACIONAL
A50: EGRESOS DE CAJA
A51: COSTOS Y GASTOS DE OPERACIÓN
A52: 2 | B52: =_xlfn.XLOOKUP(A52,Códigos!$A$421:$A$483,Códigos!$B$421:$B$483,"Verificar",0) -> Pago de Salarios a: | C52: =SUMIF('EGRESOS DE CAJA'!$B$9:$B$5958,A52,'EGRESOS DE CAJA'!$G$9:$G$5958) -> 57460000 | D52: =+C52 -> 57460000
A53: 3 | B53: =_xlfn.XLOOKUP(A53,Códigos!$A$421:$A$483,Códigos!$B$421:$B$483,"Verificar",0) -> Pago de Prestaciones sociales a: | C53: =SUMIF('EGRESOS DE CAJA'!$B$9:$B$5958,A53,'EGRESOS DE CAJA'!$G$9:$G$5958) -> 0
...

Sheet Revisión-Pruebas-Ejercicios
A1: GERMÁN TULIO FERNÁNDEZ FERNÁNDEZ
A2: REVISIONES - PRUEBAS - EJERCICIOS
A4: MOVIMIENTOS | H4: ACUMULADOS DE CAJA: Así se resume el movimiento en la caja
A6: DUQUE ECHEVERRÍ GERMÁN
A7: MOVIMIENTO DE INGRESOS A CAJA DIARIO | G7: CONTRA | H7: INGRESOS
A8: 43846 | B8: C | C8: 295 | D8: =_xlfn.XLOOKUP(B8,Códigos!$A$489:$A$522,Códigos!$B$489:$B$522,"Verificar",0) -> Recibido por: -Cuentas de cobro -DAFF | E8: =_xlfn.XLOOKUP(C8,Códigos!$A$11:$A$415,Códigos!$B$11:$B$415,"Verificar",0) -> NOMBRE 77 | F8: 600000 | H8: C | I8: =_xlfn.XLOOKUP(H8,Códigos!$A$489:$A$522,Códigos!$B$489:$B$522,"Verificar",0) -> Recibido por: -Cuentas de cobro -DAFF | J8: =SUMIF(B8,H8,F8) -> 600000
A10: MOVIMIENTO DE EGRESOS DE CAJA DIARIO | H10: EGRESOS
A11: 43846 | B11: 33 | C11: 295 | D11: =_xlfn.XLOOKUP(B11,Códigos!$A$421:$A$483,Códigos!$B$421:$B$483,"Verificar",0) -> AJUSTE POR -Consignación - Traslado a Bancos | E11: =_xlfn.XLOOKUP(C11,Códigos!$A$11:$A$415,Códigos!$B$11:$B$415,"Verificar",0) -> NOMBRE 77 | F11: 600000 | H11: 33 | I11: =_xlfn.XLOOKUP(H11,Códigos!$A$421:$A$483,Códigos!$B$421:$B$483,"Verificar",0) -> AJUSTE POR -Consignación - Traslado a Bancos | J11: =SUMIF(B11,H11,F11) -> 600000
I12: OK/Efecto neutro | J12: =+J8-J11 -> 0
C13: CARTERA del año
C14: CÓD | D14: APELLIDOS Y NOMBRES o RAZÓN SOCIAL DEL CLIENTE o TERCERO | E14: SALDOS POR COBRAR AÑOS ANTERIORES | F14: ABONOS EN EL AÑO | G14: FACTURAS y CUENTAS DE COBRO DEL AÑO | H14: INGRESOS EN EL AÑO | I14: EGRESOS EN EL AÑO | J14: SALDO TOTAL PENDIENTE POR COBRAR
C15: 295 | D15: =_xlfn.XLOOKUP(C15,Códigos!$A$11:$A$415,Códigos!$B$11:$B$415,"Verificar",0) -> NOMBRE 77 | E15: =SUMIF('CARTERA años anteriores'!$C$9:$C$133,C15,'CARTERA años anteriores'!$J$9:$J$133) -> 0 | F15: =SUMIF(FACTURACIÓN!$C$8:$C$1082,C15,FACTURACIÓN!$K$8:$K$1082) -> 900000 | G15: =SUMIF('INGRESOS A CAJA'!$C$10:$C$954,C15,'INGRESOS A CAJA'!$F$10:$F$954) -> 900000 | H15: =SUMIF('EGRESOS DE CAJA'!$C$10:$C$2251,C15,'EGRESOS DE CAJA'!$G$10:$G$2251) -> 0 | I15: =+E15+F15-G15+H15 -> 0
A19: CÁRDENAS GUTIÉRREZ SERGIO
A20: MOVIMIENTO DE INGRESOS A CAJA DIARIO | G20: CONTRA | H20: INGRESOS | K20: Consigna 5.900.000
A21: 43846 | B21: E | C21: 65 | D21: =_xlfn.XLOOKUP(B21,Códigos!$A$489:$A$522,Códigos!$B$489:$B$522,"Verificar",0) -> Ingresos Recibidos de terceros para pagos | E21: =_xlfn.XLOOKUP(C21,Códigos!$A$11:$A$415,Códigos!$B$11:$B$415,"Verificar",0) -> NOMBRE 44 | F21: 5824000 | H21: E | I21: =_xlfn.XLOOKUP(H21,Códigos!$A$489:$A$522,Códigos!$B$489:$B$522,"Verificar",0) -> Ingresos Recibidos de terceros para pagos | J21: =SUMIF(B21,H21,F21) -> 5824000
A22: 43846 | B22: D | C22: 65 | D22: =_xlfn.XLOOKUP(B22,Códigos!$A$489:$A$522,Códigos!$B$489:$B$522,"Verificar",0) -> Recibido por: -Otros ingresos Sin Facturación | E22: =_xlfn.XLOOKUP(C22,Códigos!$A$11:$A$415,Códigos!$B$11:$B$415,"Verificar",0) -> NOMBRE 44 | F22: =5900000-F21 -> 76000 | H22: D | I22: =_xlfn.XLOOKUP(H22,Códigos!$A$489:$A$522,Códigos!$B$489:$B$522,"Verificar",0) -> Recibido por: -Otros ingresos Sin Facturación | J22: =SUMIF(B22,H22,F22) -> 76000 | K22: =+J22+J21 -> 5900000
K23: OK/Consignación
A24: MOVIMIENTO DE EGRESOS DE CAJA DIARIO | H24: EGRESOS
A25: 43846 | B25: 29 | C25: 65 | D25: =_xlfn.XLOOKUP(B25,Códigos!$A$421:$A$483,Códigos!$B$421:$B$483,"Verificar",0) -> Egresos por Cuenta de Terceros -Pagos impuestos- | E25: =_xlfn.XLOOKUP(C25,Códigos!$A$11:$A$415,Códigos!$B$11:$B$415,"Verificar",0) -> NOMBRE 44 | F25: 5824000 | H25: 29 | I25: =_xlfn.XLOOKUP(H25,Códigos!$A$421:$A$483,Códigos!$B$421:$B$483,"Verificar",0) -> Egresos por Cuenta de Terceros -Pagos impuestos- | J25: =SUMIF(B25,H25,F25) -> 5824000 | K25: Se le paga el impto
A26: 43846 | B26: 33 | C26: 65 | D26: =_xlfn.XLOOKUP(B26,Códigos!$A$421:$A$483,Códigos!$B$421:$B$483,"Verificar",0) -> AJUSTE POR -Consignación - Traslado a Bancos | E26: =_xlfn.XLOOKUP(C26,Códigos!$A$11:$A$415,Códigos!$B$11:$B$415,"Verificar",0) -> NOMBRE 44 | F26: 76000 | H26: 33 | I26: =_xlfn.XLOOKUP(H26,Códigos!$A$421:$A$483,Códigos!$B$421:$B$483,"Verificar",0) -> AJUSTE POR -Consignación - Traslado a Bancos | J26: =SUMIF(B26,H26,F26) -> 76000 | K26: Nos queda a favor en el banco
A27: 43873 | B27: 31 | C27: 65 | D27: =_xlfn.XLOOKUP(B27,Códigos!$A$421:$A$483,Códigos!$B$421:$B$483,"Verificar",0) -> Egresos por Cuenta de Terceros -Certificados y otros | E27: =_xlfn.XLOOKUP(C27,Códigos!$A$11:$A$415,Códigos!$B$11:$B$415,"Verificar",0) -> NOMBRE 44 | F27: 6100 | H27: 31 | I27: =_xlfn.XLOOKUP(H27,Códigos!$A$421:$A$483,Códigos!$B$421:$B$483,"Verificar",0) -> Egresos por Cuenta de Terceros -Certificados y otros | J27: =SUMIF(B27,H27,F27) -> 6100
I28: OK/Equivale a que sacamos y prestamos efectivo | J28: =+J21+J22-J25-J26-J27 -> -6100
C29: CARTERA del año
C30: CÓD | D30: APELLIDOS Y NOMBRES o RAZÓN SOCIAL DEL CLIENTE o TERCERO | E30: SALDOS POR COBRAR AÑOS ANTERIORES | F30: ABONOS EN EL AÑO | G30: FACTURAS y CUENTAS DE COBRO DEL AÑO | H30: INGRESOS EN EL AÑO | I30: EGRESOS EN EL AÑO | J30: SALDO TOTAL PENDIENTE POR COBRAR
C31: 65 | D31: =_xlfn.XLOOKUP(C31,Códigos!$A$11:$A$415,Códigos!$B$11:$B$415,"Verificar",0) -> NOMBRE 44 | E31: =SUMIF('CARTERA años anteriores'!$C$9:$C$133,C31,'CARTERA años anteriores'!$J$9:$J$133) -> 0 | F31: =SUMIF('CARTERA años anteriores'!$C$9:$C$133,C31,'CARTERA años anteriores'!$L$9:$L$133) -> 0 | G31: =SUMIF(FACTURACIÓN!$C$8:$C$1082,C31,FACTURACIÓN!$K$8:$K$1082) -> 4170000 | H31: =SUMIF('INGRESOS A CAJA'!$C$10:$C$954,C31,'INGRESOS A CAJA'!$F$10:$F$954) -> 0 | I31: =SUMIF('EGRESOS DE CAJA'!$C$10:$C$2251,C31,'EGRESOS DE CAJA'!$G$10:$G$2251) -> 0 | J31: =+E31-F31+G31-H31+I31 -> 4170000
A34: CONSIGNACIÓN POR IDENTIFICAR
A35: MOVIMIENTO DE INGRESOS A CAJA DIARIO | G35: CONTRA | H35: INGRESOS
A36: 43839 | B36: J | C36: 0 | D36: =_xlfn.XLOOKUP(B36,Códigos!$A$489:$A$522,Códigos!$B$489:$B$522,"Verificar",0) -> -Consignaciones pendientes de identificar | E36: =_xlfn.XLOOKUP(C36,Códigos!$A$11:$A$415,Códigos!$B$11:$B$415,"Verificar",0) -> CONSIGNACIÓN POR IDENTIFICAR | F36: 1000000 | H36: J | I36: =_xlfn.XLOOKUP(H36,Códigos!$A$489:$A$522,Códigos!$B$489:$B$522,"Verificar",0) -> -Consignaciones pendientes de identificar | J36: =SUMIF(B36,H36,F36) -> 1000000
A37: MOVIMIENTO DE EGRESOS DE CAJA DIARIO | H37: EGRESOS
A38: 43839 | B38: 34 | C38: 0 | D38: =_xlfn.XLOOKUP(B38,Códigos!$A$421:$A$483,Códigos!$B$421:$B$483,"Verificar",0) -> AJUSTE POR -Consignaciones pendientes de identificar | E38: =_xlfn.XLOOKUP(C38,Códigos!$A$11:$A$415,Códigos!$B$11:$B$415,"Verificar",0) -> CONSIGNACIÓN POR IDENTIFICAR | F38: 1000000 | H38: 34 | I38: =_xlfn.XLOOKUP(H38,Códigos!$A$421:$A$483,Códigos!$B$421:$B$483,"Verificar",0) -> AJUSTE POR -Consignaciones pendientes de identificar | J38: =SUMIF(B38,H38,F38) -> 1000000
A40: MOVIMIENTO DE INGRESOS A CAJA DIARIO
A41: 43847 | B41: J | C41: 0 | D41: =_xlfn.XLOOKUP(B41,Códigos!$A$489:$A$522,Códigos!$B$489:$B$522,"Verificar",0) -> -Consignaciones pendientes de identificar | E41: =_xlfn.XLOOKUP(C41,Códigos!$A$11:$A$415,Códigos!$B$11:$B$415,"Verificar",0) -> CONSIGNACIÓN POR IDENTIFICAR | F41: 1500000 | H41: J | I41: =_xlfn.XLOOKUP(H41,Códigos!$A$489:$A$522,Códigos!$B$489:$B$522,"Verificar",0) -> -Consignaciones pendientes de identificar | J41: =SUMIF(B41,H41,F41) -> 1500000
A42: MOVIMIENTO DE EGRESOS DE CAJA DIARIO | H42: EGRESOS
A43: 43847 | B43: 34 | C43: 0 | D43: =_xlfn.XLOOKUP(B43,Códigos!$A$421:$A$483,Códigos!$B$421:$B$483,"Verificar",0) -> AJUSTE POR -Consignaciones pendientes de identificar | E43: =_xlfn.XLOOKUP(C43,Códigos!$A$11:$A$415,Códigos!$B$11:$B$415,"Verificar",0) -> CONSIGNACIÓN POR IDENTIFICAR | F43: 1500000 | H43: 34 | I43: =_xlfn.XLOOKUP(H43,Códigos!$A$421:$A$483,Códigos!$B$421:$B$483,"Verificar",0) -> AJUSTE POR -Consignaciones pendientes de identificar | J43: =SUMIF(B43,H43,F43) -> 1500000 | K43: Para no distorsionar la caja
I44: OK/Efecto neutro | J44: =+J36+J41-J38-J43 -> 0
H45: ACUMULADOS DE CAJA
H46: J | I46: =_xlfn.XLOOKUP(H46,Códigos!$A$489:$A$522,Códigos!$B$489:$B$522,"Verificar",0) -> -Consignaciones pendientes de identificar | J46: =SUMIF('INGRESOS A CAJA'!$B$9:$B$4452,H46,'INGRESOS A CAJA'!$F$9:$F$4452) -> 0 | K46: OK/Saldo final
A49: LEMOS DE GONZÁLEZ AMPARO DE JESÚS
A50: MOVIMIENTO DE INGRESOS A CAJA DIARIO | H50: INGRESOS
A51: 43848 | B51: C | C51: 122 | D51: =_xlfn.XLOOKUP(B51,Códigos!$A$489:$A$522,Códigos!$B$489:$B$522,"Verificar",0) -> Recibido por: -Cuentas de cobro -DAFF | E51: =_xlfn.XLOOKUP(C51,Códigos!$A$11:$A$415,Códigos!$B$11:$B$415,"Verificar",0) -> NOMBRE 191 | F51: 470000 | H51: C | I51: =_xlfn.XLOOKUP(H51,Códigos!$A$489:$A$522,Códigos!$B$489:$B$522,"Verificar",0) -> Recibido por: -Cuentas de cobro -DAFF | J51: =SUMIF(B51,H51,F51) -> 470000
...

Sheet Códigos
A1: LIBRO DIARIO OFICINA
A2: BASE DE DATOS Y CÓDIGOS
A3: AÑO: | B3: 2025
A5: CÓDIGO | B5: APELLIDOS Y NOMBRES o RAZÓN SOCIAL DEL CLIENTE y CONCEPTO DEL CÓDIGO | C5: OBSERVACIONES
E6: Antes reorganización
A8: CLIENTES o TERCEROS
A9: CÓDIGO | B9: APELLIDOS Y NOMBRES o RAZÓN SOCIAL DEL CLIENTE o TERCERO | C9: OBSERVACIONES
A11: 0 | B11: CONSIGNACIÓN POR IDENTIFICAR
A12: 41 | B12: NOMBRE 1
A13: 346 | B13: NOMBRE 2
A14: 300 | B14: NOMBRE 3
A15: 312 | B15: NOMBRE 4
A16: 217 | B16: NOMBRE 5
A17: 42 | B17: NOMBRE 6
A18: 43 | B18: NOMBRE 7
A19: 44 | B19: NOMBRE 8
A20: 45 | B20: NOMBRE 9
A21: 172 | B21: NOMBRE 10
A22: 156 | B22: NOMBRE 11
... A37: 341 | B37: NOMBRE 26
A38: 260 | B38: NOMBRE 27 | C38: OJO -Revisar
A39: 225 | B39: NOMBRE 28
A40: 257 | B40: NOMBRE 29
A41: 56 | B41: NOMBRE 30
A42: 353 | B42: NOMBRE 31
A43: 218 | B43: NOMBRE 32
A44: 306 | B44: NOMBRE 33
A45: 270 | B45: NOMBRE 34
A46: 4 | B46: NOMBRE 35
A47: 59 | B47: NOMBRE 36
A48: 322 | B48: NOMBRE 37 | C48: OK/
A49: 271 | B49: NOMBRE 38
A50: 60 | B50: NOMBRE 39
A51: 61 | B51: NOMBRE 40
A52: 246 | B52: NOMBRE 41
A53: 62 | B53: NOMBRE 42
A54: 63 | B54: NOMBRE 43
A55: 65 | B55: NOMBRE 44
A56: 67 | B56: NOMBRE 45
A57: 279 | B57: NOMBRE 46
...

Sheet Hoja1
A1: LIBRO DIARIO OFICINA
A2: BASE DE DATOS Y CÓDIGOS
A3: AÑO: | B3: 2024
A5: CÓDIGO | B5: APELLIDOS Y NOMBRES o RAZÓN SOCIAL DEL CLIENTE y CONCEPTO DEL CÓDIGO | C5: OBSERVACIONES
E6: Antes reorganización
A8: CLIENTES o TERCEROS
A9: CÓDIGO | B9: APELLIDOS Y NOMBRES o RAZÓN SOCIAL DEL CLIENTE o TERCERO | C9: OBSERVACIONES
A11: 0 | B11: NOMBRE 1
A12: 1 | B12: NOMBRE 2
A13: 2 | B13: NOMBRE 3
A14: 3 | B14: NOMBRE 4
A15: 4 | B15: NOMBRE 5
A16: 5 | B16: NOMBRE 6
A17: 6 | B17: NOMBRE 7
A18: 7 | B18: NOMBRE 8
A19: 8 | B19: NOMBRE 9
A20: 9 | B20: NOMBRE 10
A21: 10 | B21: NOMBRE 11
A22: 11 | B22: NOMBRE 12
... A37: 27 | B37: NOMBRE 27
A38: 28 | B38: NOMBRE 28 | C38: OJO -Revisar
A39: 29 | B39: NOMBRE 29
A40: 30 | B40: NOMBRE 30
A41: 31 | B41: NOMBRE 31
A42: 32 | B42: NOMBRE 32
A43: 33 | B43: NOMBRE 33
A44: 34 | B44: NOMBRE 34
A45: 34 | B45: NOMBRE 35
A46: 35 | B46: NOMBRE 36
A47: 36 | B47: NOMBRE 37
A48: 37 | B48: NOMBRE 38 | C48: OK/
A49: 38 | B49: NOMBRE 39
A50: 39 | B50: NOMBRE 40
A51: 40 | B51: NOMBRE 41
A52: 41 | B52: NOMBRE 42
A53: 42 | B53: NOMBRE 43
A54: 43 | B54: NOMBRE 44
A55: 44 | B55: NOMBRE 45
A56: 45 | B56: NOMBRE 46
A57: 46 | B57: NOMBRE 47
...

Sheet INGRESOS A CAJA
A1: =+Códigos!$A$1 -> LIBRO DIARIO OFICINA | F1: SALDO CRÉDITO ACUMULADO | G1: SALDO ACUMULADO | H1: La diferencia debe ser CERO (0). Si existe diferencia quiere decir que hay ERROR de formulas.
A2: MOVIMIENTO DE INGRESOS A CAJA DIARIO | F2: =F956 -> 634239583 | G2: =G956 -> 634239583 | H2: =+F2-G2 -> 0
A3: =+Códigos!$A$3 -> AÑO: | B3: 2025
A4: DESDE: | D4: 45658 | H4: =IF(H2=0,"OK Saldos","ERROR EN LAS OPERACIONES Verificar formulas") -> OK Saldos
A5: HASTA: | D5: 46022
A7: FECHA | B7: CÓDIGO DEL INGRESO | C7: CÓDIGO DEL TERCERO | D7: CONCEPTO DEL INGRESO | E7: APELLIDOS Y NOMBRES o RAZÓN SOCIAL DEL CLIENTE o TERCERO | F7: CRÉDITOS | G7: SALDO ACUMULADO | H7: DETALLE | I7: REVISIÓN
A10: =+D4 -> 45658 | F10: 0 | G10: =F10 -> 0
A12: 45659 | B12: I | C12: 5 | D12: =_xlfn.XLOOKUP(B12,Códigos!$A$489:$A$522,Códigos!$B$489:$B$522,"Verificar",0) -> -Retiros y Traslados de Bancos | E12: =_xlfn.XLOOKUP(C12,Códigos!$A$11:$A$415,Códigos!$B$11:$B$415,"Verificar",0) -> NOMBRE 25 | F12: 50000 | G12: =+G11+F12 -> 50000 | H12: Recarga Flypass Barbosa
A13: 45660 | B13: I | C13: 5 | D13: =_xlfn.XLOOKUP(B13,Códigos!$A$489:$A$522,Códigos!$B$489:$B$522,"Verificar",0) -> -Retiros y Traslados de Bancos | E13: =_xlfn.XLOOKUP(C13,Códigos!$A$11:$A$415,Códigos!$B$11:$B$415,"Verificar",0) -> NOMBRE 25 | F13: 500000 | G13: =+G12+F13 -> 550000 | H13: Traslado pedro pago camaras
A14: 45660 | B14: C | C14: 182 | D14: =_xlfn.XLOOKUP(B14,Códigos!$A$489:$A$522,Códigos!$B$489:$B$522,"Verificar",0) -> Recibido por: -Cuentas de cobro -DAFF | E14: =_xlfn.XLOOKUP(C14,Códigos!$A$11:$A$415,Códigos!$B$11:$B$415,"Verificar",0) -> NOMBRE 317 | F14: 1800000 | G14: =+G13+F14 -> 2350000 | H14: Pago Cuenta 24-105
A15: 45666 | B15: I | C15: 5 | D15: =_xlfn.XLOOKUP(B15,Códigos!$A$489:$A$522,Códigos!$B$489:$B$522,"Verificar",0) -> -Retiros y Traslados de Bancos | E15: =_xlfn.XLOOKUP(C15,Códigos!$A$11:$A$415,Códigos!$B$11:$B$415,"Verificar",0) -> NOMBRE 25 | F15: 47500 | G15: =+G14+F15 -> 2397500 | H15: Pago Movistar Diego
A16: 45670 | B16: I | C16: 5 | D16: =_xlfn.XLOOKUP(B16,Códigos!$A$489:$A$522,Códigos!$B$489:$B$522,"Verificar",0) -> -Retiros y Traslados de Bancos | E16: =_xlfn.XLOOKUP(C16,Códigos!$A$11:$A$415,Códigos!$B$11:$B$415,"Verificar",0) -> NOMBRE 25 | F16: 125800 | G16: =+G15+F16 -> 2523300 | H16: Pago Tigo Babilonia enero
A17: 45671 | B17: I | C17: 5 | D17: =_xlfn.XLOOKUP(B17,Códigos!$A$489:$A$522,Códigos!$B$489:$B$522,"Verificar",0) -> -Retiros y Traslados de Bancos | E17: =_xlfn.XLOOKUP(C17,Códigos!$A$11:$A$415,Códigos!$B$11:$B$415,"Verificar",0) -> NOMBRE 25 | F17: 1000600 | G17: =+G16+F17 -> 3523900 | H17: Pago Seguridad Social Empleados febrero
A18: 45671 | B18: I | C18: 5 | D18: =_xlfn.XLOOKUP(B18,Códigos!$A$489:$A$522,Códigos!$B$489:$B$522,"Verificar",0) -> -Retiros y Traslados de Bancos | E18: =_xlfn.XLOOKUP(C18,Códigos!$A$11:$A$415,Códigos!$B$11:$B$415,"Verificar",0) -> NOMBRE 25 | F18: 897800 | G18: =+G17+F18 -> 4421700 | H18: Pago Seguridad Social Independiente enero
A19: 45671 | B19: I | C19: 5 | D19: =_xlfn.XLOOKUP(B19,Códigos!$A$489:$A$522,Códigos!$B$489:$B$522,"Verificar",0) -> -Retiros y Traslados de Bancos | E19: =_xlfn.XLOOKUP(C19,Códigos!$A$11:$A$415,Códigos!$B$11:$B$415,"Verificar",0) -> NOMBRE 25 | F19: 350000 | G19: =+G18+F19 -> 4771700 | H19: Abono intererses cuota enero 2025
A20: 45671 | B20: I | C20: 5 | D20: =_xlfn.XLOOKUP(B20,Códigos!$A$489:$A$522,Códigos!$B$489:$B$522,"Verificar",0) -> -Retiros y Traslados de Bancos | E20: =_xlfn.XLOOKUP(C20,Códigos!$A$11:$A$415,Códigos!$B$11:$B$415,"Verificar",0) -> NOMBRE 25 | F20: 200000 | G20: =+G19+F20 -> 4971700 | H20: Abono a deuda enero 2025
A21: 45671 | B21: I | C21: 5 | D21: =_xlfn.XLOOKUP(B21,Códigos!$A$489:$A$522,Códigos!$B$489:$B$522,"Verificar",0) -> -Retiros y Traslados de Bancos | E21: =_xlfn.XLOOKUP(C21,Códigos!$A$11:$A$415,Códigos!$B$11:$B$415,"Verificar",0) -> NOMBRE 25 | F21: 89300 | G21: =+G20+F21 -> 5061000 | H21: Pago EPM Barbosa
A22: 45671 | B22: I | C22: 5 | D22: =_xlfn.XLOOKUP(B22,Códigos!$A$489:$A$522,Códigos!$B$489:$B$522,"Verificar",0) -> -Retiros y Traslados de Bancos | E22: =_xlfn.XLOOKUP(C22,Códigos!$A$11:$A$415,Códigos!$B$11:$B$415,"Verificar",0) -> NOMBRE 25 | F22: 67800 | G22: =+G21+F22 -> 5128800 | H22: Pago EPM Carolina
A23: 45671 | B23: I | C23: 5 | D23: =_xlfn.XLOOKUP(B23,Códigos!$A$489:$A$522,Códigos!$B$489:$B$522,"Verificar",0) -> -Retiros y Traslados de Bancos | E23: =_xlfn.XLOOKUP(C23,Códigos!$A$11:$A$415,Códigos!$B$11:$B$415,"Verificar",0) -> NOMBRE 25 | F23: =1030000-F25-F24 -> 170000 | G23: =+G22+F23 -> 5298800 | H23: Pago cita perros
A24: 45671 | B24: I | C24: 5 | D24: =_xlfn.XLOOKUP(B24,Códigos!$A$489:$A$522,Códigos!$B$489:$B$522,"Verificar",0) -> -Retiros y Traslados de Bancos | E24: =_xlfn.XLOOKUP(C24,Códigos!$A$11:$A$415,Códigos!$B$11:$B$415,"Verificar",0) -> NOMBRE 25 | F24: 200000 | G24: =+G23+F24 -> 5498800 | H24: Pago mesada tranporte U de A
A25: 45671 | B25: I | C25: 5 | D25: =_xlfn.XLOOKUP(B25,Códigos!$A$489:$A$522,Códigos!$B$489:$B$522,"Verificar",0) -> -Retiros y Traslados de Bancos | E25: =_xlfn.XLOOKUP(C25,Códigos!$A$11:$A$415,Códigos!$B$11:$B$415,"Verificar",0) -> NOMBRE 25 | F25: 660000 | G25: =+G24+F25 -> 6158800 | H25: Mesada Semana 13 al 19 enero
A26: 45671 | B26: A | C26: 25 | D26: =_xlfn.XLOOKUP(B26,Códigos!$A$489:$A$522,Códigos!$B$489:$B$522,"Verificar",0) -> Recibido por: -FACTURAS -GTFF | E26: =_xlfn.XLOOKUP(C26,Códigos!$A$11:$A$415,Códigos!$B$11:$B$415,"Verificar",0) -> NOMBRE 178 | F26: 5164600 | G26: =+G25+F26 -> 11323400 | H26: Pago factura GTFF-126
A27: 45671 | B27: A | C27: 158 | D27: =_xlfn.XLOOKUP(B27,Códigos!$A$489:$A$522,Códigos!$B$489:$B$522,"Verificar",0) -> Recibido por: -FACTURAS -GTFF | E27: =_xlfn.XLOOKUP(C27,Códigos!$A$11:$A$415,Códigos!$B$11:$B$415,"Verificar",0) -> NOMBRE 262 | F27: 3308200 | G27: =+G26+F27 -> 14631600 | H27: Pago factura GTFF-128
A28: 45671 | B28: A | C28: 296 | D28: =_xlfn.XLOOKUP(B28,Códigos!$A$489:$A$522,Códigos!$B$489:$B$522,"Verificar",0) -> Recibido por: -FACTURAS -GTFF | E28: =_xlfn.XLOOKUP(C28,Códigos!$A$11:$A$415,Códigos!$B$11:$B$415,"Verificar",0) -> NOMBRE 300 | F28: 1035300 | G28: =+G27+F28 -> 15666900 | H28: Pago factura GTFF-129
A29: 45671 | B29: A | C29: 25 | D29: =_xlfn.XLOOKUP(B29,Códigos!$A$489:$A$522,Códigos!$B$489:$B$522,"Verificar",0) -> Recibido por: -FACTURAS -GTFF | E29: =_xlfn.XLOOKUP(C29,Códigos!$A$11:$A$415,Códigos!$B$11:$B$415,"Verificar",0) -> NOMBRE 178 | F29: 4611600 | G29: =+G28+F29 -> 20278500 | H29: Pago factura GTFF-159
A30: 45671 | B30: A | C30: 158 | D30: =_xlfn.XLOOKUP(B30,Códigos!$A$489:$A$522,Códigos!$B$489:$B$522,"Verificar",0) -> Recibido por: -FACTURAS -GTFF | E30: =_xlfn.XLOOKUP(C30,Códigos!$A$11:$A$415,Códigos!$B$11:$B$415,"Verificar",0) -> NOMBRE 262 | F30: 3629500 | G30: =+G29+F30 -> 23908000 | H30: Pago factura GTFF-161
A31: 45671 | B31: A | C31: 296 | D31: =_xlfn.XLOOKUP(B31,Códigos!$A$489:$A$522,Códigos!$B$489:$B$522,"Verificar",0) -> Recibido por: -FACTURAS -GTFF | E31: =_xlfn.XLOOKUP(C31,Códigos!$A$11:$A$415,Códigos!$B$11:$B$415,"Verificar",0) -> NOMBRE 300 | F31: 1130500 | G31: =+G30+F31 -> 25038500 | H31: Pago factura GTFF-162
A32: 45671 | B32: I | C32: 3 | D32: =_xlfn.XLOOKUP(B32,Códigos!$A$489:$A$522,Códigos!$B$489:$B$522,"Verificar",0) -> -Retiros y Traslados de Bancos | E32: =_xlfn.XLOOKUP(C32,Códigos!$A$11:$A$415,Códigos!$B$11:$B$415,"Verificar",0) -> NOMBRE 24 | F32: 35000000 | G32: =+G31+F32 -> 60038500 | H32: Abono a deuda consignado Inversion Virtual
A33: 45672 | B33: C | C33: 133 | D33: =_xlfn.XLOOKUP(B33,Códigos!$A$489:$A$522,Códigos!$B$489:$B$522,"Verificar",0) -> Recibido por: -Cuentas de cobro -DAFF | E33: =_xlfn.XLOOKUP(C33,Códigos!$A$11:$A$415,Códigos!$B$11:$B$415,"Verificar",0) -> NOMBRE 216 | F33: 1160000 | G33: =+G32+F33 -> 61198500 | H33: Pago Cuenta 24-146
A34: 45672 | B34: I | C34: 3 | D34: =_xlfn.XLOOKUP(B34,Códigos!$A$489:$A$522,Códigos!$B$489:$B$522,"Verificar",0) -> -Retiros y Traslados de Bancos | E34: =_xlfn.XLOOKUP(C34,Códigos!$A$11:$A$415,Códigos!$B$11:$B$415,"Verificar",0) -> NOMBRE 24 | F34: 2000000 | G34: =+G33+F34 -> 63198500 | H34: Retiro por cajero
A35: 45673 | B35: I | C35: 5 | D35: =_xlfn.XLOOKUP(B35,Códigos!$A$489:$A$522,Códigos!$B$489:$B$522,"Verificar",0) -> -Retiros y Traslados de Bancos | E35: =_xlfn.XLOOKUP(C35,Códigos!$A$11:$A$415,Códigos!$B$11:$B$415,"Verificar",0) -> NOMBRE 25 | F35: 1026800 | G35: =+G34+F35 -> 64225300 | H35: Pago credito hipotecario
... A229: 45792 | B229: I | C229: 5 | D229: =_xlfn.XLOOKUP(B229,Códigos!$A$489:$A$522,Códigos!$B$489:$B$522,"Verificar",0) -> -Retiros y Traslados de Bancos | E229: =_xlfn.XLOOKUP(C229,Códigos!$A$11:$A$415,Códigos!$B$11:$B$415,"Verificar",0) -> NOMBRE 25 | F229: 660000 | G229: =+G228+F229 -> 404661294 | H229: Pago Nomina 12 al 18 mayo
A230: 45792 | B230: I | C230: 5 | D230: =_xlfn.XLOOKUP(B230,Códigos!$A$489:$A$522,Códigos!$B$489:$B$522,"Verificar",0) -> -Retiros y Traslados de Bancos | E230: =_xlfn.XLOOKUP(C230,Códigos!$A$11:$A$415,Códigos!$B$11:$B$415,"Verificar",0) -> NOMBRE 25 | F230: =1320000-F229-F228-2000 -> 438000 | G230: =+G229+F230 -> 405099294 | H230: Pago IMP PATR 2025
A231: 45793 | B231: I | C231: 5 | D231: =_xlfn.XLOOKUP(B231,Códigos!$A$489:$A$522,Códigos!$B$489:$B$522,"Verificar",0) -> -Retiros y Traslados de Bancos | E231: =_xlfn.XLOOKUP(C231,Códigos!$A$11:$A$415,Códigos!$B$11:$B$415,"Verificar",0) -> NOMBRE 25 | F231: 2000000 | G231: =+G230+F231 -> 407099294 | H231: Retiro por cajero
A232: 45793 | B232: I | C232: 5 | D232: =_xlfn.XLOOKUP(B232,Códigos!$A$489:$A$522,Códigos!$B$489:$B$522,"Verificar",0) -> -Retiros y Traslados de Bancos | E232: =_xlfn.XLOOKUP(C232,Códigos!$A$11:$A$415,Códigos!$B$11:$B$415,"Verificar",0) -> NOMBRE 25 | F232: 1026800 | G232: =+G231+F232 -> 408126094 | H232: Pago credito hipotecario
A233: 45797 | B233: I | C233: 5 | D233: =_xlfn.XLOOKUP(B233,Códigos!$A$489:$A$522,Códigos!$B$489:$B$522,"Verificar",0) -> -Retiros y Traslados de Bancos | E233: =_xlfn.XLOOKUP(C233,Códigos!$A$11:$A$415,Códigos!$B$11:$B$415,"Verificar",0) -> NOMBRE 25 | F233: =266130+383130 -> 649260 | G233: =+G232+F233 -> 408775354 | H233: Pago Administracion del Gaspar de Rodas
A234: 45799 | B234: I | C234: 5 | D234: =_xlfn.XLOOKUP(B234,Códigos!$A$489:$A$522,Códigos!$B$489:$B$522,"Verificar",0) -> -Retiros y Traslados de Bancos | E234: =_xlfn.XLOOKUP(C234,Códigos!$A$11:$A$415,Códigos!$B$11:$B$415,"Verificar",0) -> NOMBRE 25 | F234: 220000 | G234: =+G233+F234 -> 408995354 | H234: Pago mesada tranporte U de A
A235: 45799 | B235: I | C235: 5 | D235: =_xlfn.XLOOKUP(B235,Códigos!$A$489:$A$522,Códigos!$B$489:$B$522,"Verificar",0) -> -Retiros y Traslados de Bancos | E235: =_xlfn.XLOOKUP(C235,Códigos!$A$11:$A$415,Códigos!$B$11:$B$415,"Verificar",0) -> NOMBRE 25 | F235: 660000 | G235: =+G234+F235 -> 409655354 | H235: Pago Nomina 19 al 25 mayo
A236: 45799 | B236: I | C236: 5 | D236: =_xlfn.XLOOKUP(B236,Códigos!$A$489:$A$522,Códigos!$B$489:$B$522,"Verificar",0) -> -Retiros y Traslados de Bancos | E236: =_xlfn.XLOOKUP(C236,Códigos!$A$11:$A$415,Códigos!$B$11:$B$415,"Verificar",0) -> NOMBRE 25 | F236: 2000000 | G236: =+G235+F236 -> 411655354 | H236: Retiro por cajero
A237: 45805 | B237: I | C237: 5 | D237: =_xlfn.XLOOKUP(B237,Códigos!$A$489:$A$522,Códigos!$B$489:$B$522,"Verificar",0) -> -Retiros y Traslados de Bancos | E237: =_xlfn.XLOOKUP(C237,Códigos!$A$11:$A$415,Códigos!$B$11:$B$415,"Verificar",0) -> NOMBRE 25 | F237: 2000000 | G237: =+G236+F237 -> 413655354 | H237: Retiro por cajero
...

Sheet EGRESOS DE CAJA
A1: =+Códigos!$A$1 -> LIBRO DIARIO OFICINA | G1: SALDO DÉBITO ACUMULADO | H1: SALDO ACUMULADO | I1: La diferencia debe ser CERO (0). Si existe diferencia quiere decir que hay ERROR de formulas.
A2: MOVIMIENTO DE EGRESOS DE CAJA DIARIO | G2: =+G2253 -> 633732083 | H2: =+H2253 -> 633732083 | I2: =+G2-H2 -> 0
A3: =+Códigos!$A$3 -> AÑO: | B3: 2025
A4: DESDE: | D4: =+'INGRESOS A CAJA'!D4 -> 45658 | I4: =IF(I2=0,"OK Saldos","ERROR EN LAS OPERACIONES Verificar formulas") -> OK Saldos
A5: HASTA: | D5: =+'INGRESOS A CAJA'!D5 -> 46022
A7: FECHA | B7: CÓDIGO DEL EGRESO | C7: CÓDIGO DEL TERCERO | D7: CONCEPTO DEL EGRESO | E7: APELLIDOS Y NOMBRES o RAZÓN SOCIAL DEL CLIENTE o TERCERO | F7: ETIQUETA | G7: DÉBITOS | H7: SALDO ACUMULADO | I7: OBSERVACIONES | J7: REVISIÓN
A12: 45659 | B12: 37 | C12: 359 | D12: =_xlfn.XLOOKUP(B12,Códigos!$A$421:$A$483,Códigos!$B$421:$B$483,"Verificar",0) -> Gastos Barbosa | E12: =_xlfn.XLOOKUP(C12,Códigos!$A$11:$A$415,Códigos!$B$11:$B$415,"Verificar",0) -> NOMBRE 232 | F12: GTFF | G12: 50000 | H12: =+H11+G12 -> 50000 | I12: Recarga Flypass Barbosa
A13: 45660 | B13: 22 | C13: 359 | D13: =_xlfn.XLOOKUP(B13,Códigos!$A$421:$A$483,Códigos!$B$421:$B$483,"Verificar",0) -> Compra de: -Equipos, dotaciones y repuestos para oficina | E13: =_xlfn.XLOOKUP(C13,Códigos!$A$11:$A$415,Códigos!$B$11:$B$415,"Verificar",0) -> NOMBRE 232 | F13: OFICINA | G13: 500000 | H13: =+H12+G13 -> 550000 | I13: Traslado pedro pago camaras
A14: 45660 | B14: 33 | C14: 3 | D14: =_xlfn.XLOOKUP(B14,Códigos!$A$421:$A$483,Códigos!$B$421:$B$483,"Verificar",0) -> AJUSTE POR -Consignación - Traslado a Bancos | E14: =_xlfn.XLOOKUP(C14,Códigos!$A$11:$A$415,Códigos!$B$11:$B$415,"Verificar",0) -> NOMBRE 24 | G14: 1800000 | H14: =+H13+G14 -> 2350000 | I14: Pago Cuenta 24-105
A15: 45666 | B15: 12 | C15: 359 | D15: =_xlfn.XLOOKUP(B15,Códigos!$A$421:$A$483,Códigos!$B$421:$B$483,"Verificar",0) -> Pagos de: -Celulares | E15: =_xlfn.XLOOKUP(C15,Códigos!$A$11:$A$415,Códigos!$B$11:$B$415,"Verificar",0) -> NOMBRE 232 | F15: GTFF | G15: 47500 | H15: =+H14+G15 -> 2397500 | I15: Pago Movistar Diego
A16: 45670 | B16: 10 | C16: 359 | D16: =_xlfn.XLOOKUP(B16,Códigos!$A$421:$A$483,Códigos!$B$421:$B$483,"Verificar",0) -> Pagos de: -Servicios públicos -NIÑAS- | E16: =_xlfn.XLOOKUP(C16,Códigos!$A$11:$A$415,Códigos!$B$11:$B$415,"Verificar",0) -> NOMBRE 232 | F16: GTFF | G16: 125800 | H16: =+H15+G16 -> 2523300 | I16: Pago Tigo Babilonia enero
A17: 45671 | B17: 7 | C17: 359 | D17: =_xlfn.XLOOKUP(B17,Códigos!$A$421:$A$483,Códigos!$B$421:$B$483,"Verificar",0) -> Pagos de: -Seguridad Social | E17: =_xlfn.XLOOKUP(C17,Códigos!$A$11:$A$415,Códigos!$B$11:$B$415,"Verificar",0) -> NOMBRE 232 | F17: OFICINA | G17: 1000600 | H17: =+H16+G17 -> 3523900 | I17: Pago Seguridad Social Empleados febrero
A18: 45671 | B18: 7 | C18: 359 | D18: =_xlfn.XLOOKUP(B18,Códigos!$A$421:$A$483,Códigos!$B$421:$B$483,"Verificar",0) -> Pagos de: -Seguridad Social | E18: =_xlfn.XLOOKUP(C18,Códigos!$A$11:$A$415,Códigos!$B$11:$B$415,"Verificar",0) -> NOMBRE 232 | F18: OFICINA | G18: 897800 | H18: =+H17+G18 -> 4421700 | I18: Pago Seguridad Social Independiente enero
A19: 45671 | B19: 39 | C19: 362 | D19: =_xlfn.XLOOKUP(B19,Códigos!$A$421:$A$483,Códigos!$B$421:$B$483,"Verificar",0) -> Pago intereses préstamo Juliana | E19: =_xlfn.XLOOKUP(C19,Códigos!$A$11:$A$415,Códigos!$B$11:$B$415,"Verificar",0) -> NOMBRE 97 | F19: OFICINA | G19: 350000 | H19: =+H18+G19 -> 4771700 | I19: Abono intererses cuota enero 2025
A20: 45671 | B20: 21 | C20: 362 | D20: =_xlfn.XLOOKUP(B20,Códigos!$A$421:$A$483,Códigos!$B$421:$B$483,"Verificar",0) -> Pagos de: -Cuentas por Pagar a: | E20: =_xlfn.XLOOKUP(C20,Códigos!$A$11:$A$415,Códigos!$B$11:$B$415,"Verificar",0) -> NOMBRE 97 | F20: OFICINA | G20: 200000 | H20: =+H19+G20 -> 4971700 | I20: Abono a deuda enero 2025
A21: 45671 | B21: 9 | C21: 359 | D21: =_xlfn.XLOOKUP(B21,Códigos!$A$421:$A$483,Códigos!$B$421:$B$483,"Verificar",0) -> Pagos de: -Servicios públicos -OFICINA- | E21: =_xlfn.XLOOKUP(C21,Códigos!$A$11:$A$415,Códigos!$B$11:$B$415,"Verificar",0) -> NOMBRE 232 | F21: OFICINA | G21: 89300 | H21: =+H20+G21 -> 5061000 | I21: Pago EPM Barbosa
A22: 45671 | B22: 9 | C22: 359 | D22: =_xlfn.XLOOKUP(B22,Códigos!$A$421:$A$483,Códigos!$B$421:$B$483,"Verificar",0) -> Pagos de: -Servicios públicos -OFICINA- | E22: =_xlfn.XLOOKUP(C22,Códigos!$A$11:$A$415,Códigos!$B$11:$B$415,"Verificar",0) -> NOMBRE 232 | F22: OFICINA | G22: 67800 | H22: =+H21+G22 -> 5128800 | I22: Pago EPM Carolina
A23: 45671 | B23: 8 | C23: 357 | D23: =_xlfn.XLOOKUP(B23,Códigos!$A$421:$A$483,Códigos!$B$421:$B$483,"Verificar",0) -> Pagos de: -Cuota para alimentos y Manuntención | E23: =_xlfn.XLOOKUP(C23,Códigos!$A$11:$A$415,Códigos!$B$11:$B$415,"Verificar",0) -> NOMBRE 107 | F23: GTFF | G23: =1030000-G25-G24 -> 150000 | H23: =+H22+G23 -> 5278800 | I23: Pago cita perros
A24: 45671 | B24: 8 | C24: 357 | D24: =_xlfn.XLOOKUP(B24,Códigos!$A$421:$A$483,Códigos!$B$421:$B$483,"Verificar",0) -> Pagos de: -Cuota para alimentos y Manuntención | E24: =_xlfn.XLOOKUP(C24,Códigos!$A$11:$A$415,Códigos!$B$11:$B$415,"Verificar",0) -> NOMBRE 107 | F24: GTFF | G24: 220000 | H24: =+H23+G24 -> 5498800 | I24: Pago mesada tranporte U de A
A25: 45671 | B25: 2 | C25: 353 | D25: =_xlfn.XLOOKUP(B25,Códigos!$A$421:$A$483,Códigos!$B$421:$B$483,"Verificar",0) -> Pago de Salarios a: | E25: =_xlfn.XLOOKUP(C25,Códigos!$A$11:$A$415,Códigos!$B$11:$B$415,"Verificar",0) -> NOMBRE 31 | F25: OFICINA | G25: 660000 | H25: =+H24+G25 -> 6158800 | I25: Pago Nomina 13 al 19 enero
A26: 45671 | B26: 33 | C26: 5 | D26: =_xlfn.XLOOKUP(B26,Códigos!$A$421:$A$483,Códigos!$B$421:$B$483,"Verificar",0) -> AJUSTE POR -Consignación - Traslado a Bancos | E26: =_xlfn.XLOOKUP(C26,Códigos!$A$11:$A$415,Códigos!$B$11:$B$415,"Verificar",0) -> NOMBRE 25 | G26: 5164600 | H26: =+H25+G26 -> 11323400 | I26: Pago factura GTFF-126
A27: 45671 | B27: 33 | C27: 5 | D27: =_xlfn.XLOOKUP(B27,Códigos!$A$421:$A$483,Códigos!$B$421:$B$483,"Verificar",0) -> AJUSTE POR -Consignación - Traslado a Bancos | E27: =_xlfn.XLOOKUP(C27,Códigos!$A$11:$A$415,Códigos!$B$11:$B$415,"Verificar",0) -> NOMBRE 25 | G27: 3308200 | H27: =+H26+G27 -> 14631600 | I27: Pago factura GTFF-128
A28: 45671 | B28: 33 | C28: 5 | D28: =_xlfn.XLOOKUP(B28,Códigos!$A$421:$A$483,Códigos!$B$421:$B$483,"Verificar",0) -> AJUSTE POR -Consignación - Traslado a Bancos | E28: =_xlfn.XLOOKUP(C28,Códigos!$A$11:$A$415,Códigos!$B$11:$B$415,"Verificar",0) -> NOMBRE 25 | G28: 1035300 | H28: =+H27+G28 -> 15666900 | I28: Pago factura GTFF-129
A29: 45671 | B29: 33 | C29: 3 | D29: =_xlfn.XLOOKUP(B29,Códigos!$A$421:$A$483,Códigos!$B$421:$B$483,"Verificar",0) -> AJUSTE POR -Consignación - Traslado a Bancos | E29: =_xlfn.XLOOKUP(C29,Códigos!$A$11:$A$415,Códigos!$B$11:$B$415,"Verificar",0) -> NOMBRE 24 | G29: 35000000 | H29: =+H28+G29 -> 50666900 | I29: Abono a deuda consignado Inversion Virtual
A30: 45671 | B30: 33 | C30: 5 | D30: =_xlfn.XLOOKUP(B30,Códigos!$A$421:$A$483,Códigos!$B$421:$B$483,"Verificar",0) -> AJUSTE POR -Consignación - Traslado a Bancos | E30: =_xlfn.XLOOKUP(C30,Códigos!$A$11:$A$415,Códigos!$B$11:$B$415,"Verificar",0) -> NOMBRE 25 | G30: 4611600 | H30: =+H29+G30 -> 55278500 | I30: Pago factura GTFF-159
A31: 45671 | B31: 33 | C31: 5 | D31: =_xlfn.XLOOKUP(B31,Códigos!$A$421:$A$483,Códigos!$B$421:$B$483,"Verificar",0) -> AJUSTE POR -Consignación - Traslado a Bancos | E31: =_xlfn.XLOOKUP(C31,Códigos!$A$11:$A$415,Códigos!$B$11:$B$415,"Verificar",0) -> NOMBRE 25 | G31: 3629500 | H31: =+H30+G31 -> 58908000 | I31: Pago factura GTFF-161
A32: 45671 | B32: 33 | C32: 5 | D32: =_xlfn.XLOOKUP(B32,Códigos!$A$421:$A$483,Códigos!$B$421:$B$483,"Verificar",0) -> AJUSTE POR -Consignación - Traslado a Bancos | E32: =_xlfn.XLOOKUP(C32,Códigos!$A$11:$A$415,Códigos!$B$11:$B$415,"Verificar",0) -> NOMBRE 25 | G32: 1130500 | H32: =+H31+G32 -> 60038500 | I32: Pago factura GTFF-162
A33: 45672 | B33: 27 | C33: 359 | D33: =_xlfn.XLOOKUP(B33,Códigos!$A$421:$A$483,Códigos!$B$421:$B$483,"Verificar",0) -> Compra de: -Restaurante y cafetería | E33: =_xlfn.XLOOKUP(C33,Códigos!$A$11:$A$415,Códigos!$B$11:$B$415,"Verificar",0) -> NOMBRE 232 | F33: OFICINA | G33: 400000 | H33: =+H32+G33 -> 60438500 | I33: Cuota del Mercado -DAFF-
A34: 45672 | B34: 33 | C34: 3 | D34: =_xlfn.XLOOKUP(B34,Códigos!$A$421:$A$483,Códigos!$B$421:$B$483,"Verificar",0) -> AJUSTE POR -Consignación - Traslado a Bancos | E34: =_xlfn.XLOOKUP(C34,Códigos!$A$11:$A$415,Códigos!$B$11:$B$415,"Verificar",0) -> NOMBRE 24 | G34: 1160000 | H34: =+H33+G34 -> 61598500 | I34: Pago Cuenta 24-146
A35: 45672 | B35: 1 | C35: 355 | D35: =_xlfn.XLOOKUP(B35,Códigos!$A$421:$A$483,Códigos!$B$421:$B$483,"Verificar",0) -> Gastos personales | E35: =_xlfn.XLOOKUP(C35,Códigos!$A$11:$A$415,Códigos!$B$11:$B$415,"Verificar",0) -> NOMBRE 96 | F35: GTFF | G35: 200000 | H35: =+H34+G35 -> 61798500 | I35: Gastos combustible Barbosa
A36: 45672 | B36: 23 | C36: 359 | D36: =_xlfn.XLOOKUP(B36,Códigos!$A$421:$A$483,Códigos!$B$421:$B$483,"Verificar",0) -> Compra de: -Útiles de aseo | E36: =_xlfn.XLOOKUP(C36,Códigos!$A$11:$A$415,Códigos!$B$11:$B$415,"Verificar",0) -> NOMBRE 232 | F36: OFICINA | G36: 80000 | H36: =+H35+G36 -> 61878500 | I36: Pago Aseo oficinas 604 al 608
A37: 45673 | B37: 8 | C37: 359 | D37: =_xlfn.XLOOKUP(B37,Códigos!$A$421:$A$483,Códigos!$B$421:$B$483,"Verificar",0) -> Pagos de: -Cuota para alimentos y Manuntención | E37: =_xlfn.XLOOKUP(C37,Códigos!$A$11:$A$415,Códigos!$B$11:$B$415,"Verificar",0) -> NOMBRE 232 | F37: OFICINA | G37: 198000 | H37: =+H36+G37 -> 62076500 | I37: Pago administracion Babilonia enero
A38: 45673 | B38: 1 | C38: 359 | D38: =_xlfn.XLOOKUP(B38,Códigos!$A$421:$A$483,Códigos!$B$421:$B$483,"Verificar",0) -> Gastos personales | E38: =_xlfn.XLOOKUP(C38,Códigos!$A$11:$A$415,Códigos!$B$11:$B$415,"Verificar",0) -> NOMBRE 232 | F38: OFICINA | G38: 690000 | H38: =+H37+G38 -> 62766500 | I38: Pago matricula Maria Jose
A39: 45673 | B39: 33 | C39: 3 | D39: =_xlfn.XLOOKUP(B39,Códigos!$A$421:$A$483,Códigos!$B$421:$B$483,"Verificar",0) -> AJUSTE POR -Consignación - Traslado a Bancos | E39: =_xlfn.XLOOKUP(C39,Códigos!$A$11:$A$415,Códigos!$B$11:$B$415,"Verificar",0) -> NOMBRE 24 | F39: OFICINA | G39: 50000 | H39: =+H38+G39 -> 62816500 | I39: Consignados a Diego de Ivan Velez
A40: 45673 | B40: 43 | C40: 359 | D40: =_xlfn.XLOOKUP(B40,Códigos!$A$421:$A$483,Códigos!$B$421:$B$483,"Verificar",0) -> Pago Hipotecario BANCOLOMBIA | E40: =_xlfn.XLOOKUP(C40,Códigos!$A$11:$A$415,Códigos!$B$11:$B$415,"Verificar",0) -> NOMBRE 232 | F40: OFICINA | G40: 1026800 | H40: =+H39+G40 -> 63843300 | I40: Pago credito hipotecario
A41: 45674 | B41: 27 | C41: 359 | D41: =_xlfn.XLOOKUP(B41,Códigos!$A$421:$A$483,Códigos!$B$421:$B$483,"Verificar",0) -> Compra de: -Restaurante y cafetería | E41: =_xlfn.XLOOKUP(C41,Códigos!$A$11:$A$415,Códigos!$B$11:$B$415,"Verificar",0) -> NOMBRE 232 | F41: OFICINA | G41: 38000 | H41: =+H40+G41 -> 63881300 | I41: Compra dispensador agua
A42: 45674 | B42: 27 | C42: 359 | D42: =_xlfn.XLOOKUP(B42,Códigos!$A$421:$A$483,Códigos!$B$421:$B$483,"Verificar",0) -> Compra de: -Restaurante y cafetería | E42: =_xlfn.XLOOKUP(C42,Códigos!$A$11:$A$415,Códigos!$B$11:$B$415,"Verificar",0) -> NOMBRE 232 | F42: OFICINA | G42: 88000 | H42: =+H41+G42 -> 63969300 | I42: Compra almuerzos oficinay Tintos
A43: 45674 | B43: 33 | C43: 5 | D43: =_xlfn.XLOOKUP(B43,Códigos!$A$421:$A$483,Códigos!$B$421:$B$483,"Verificar",0) -> AJUSTE POR -Consignación - Traslado a Bancos | E43: =_xlfn.XLOOKUP(C43,Códigos!$A$11:$A$415,Códigos!$B$11:$B$415,"Verificar",0) -> NOMBRE 25 | G43: 11983300 | H43: =+H42+G43 -> 75952600 | I43: Pago factura GTFF-127 y abono factura GTFF-160
A44: 45674 | B44: 33 | C44: 5 | D44: =_xlfn.XLOOKUP(B44,Códigos!$A$421:$A$483,Códigos!$B$421:$B$483,"Verificar",0) -> AJUSTE POR -Consignación - Traslado a Bancos | E44: =_xlfn.XLOOKUP(C44,Códigos!$A$11:$A$415,Códigos!$B$11:$B$415,"Verificar",0) -> NOMBRE 25 | G44: 5000000 | H44: =+H43+G44 -> 80952600 | I44: Pago factura GTFF-156 y abono factura GTFF-157
A45: 45674 | B45: 8 | C45: 356 | D45: =_xlfn.XLOOKUP(B45,Códigos!$A$421:$A$483,Códigos!$B$421:$B$483,"Verificar",0) -> Pagos de: -Cuota para alimentos y Manuntención | E45: =_xlfn.XLOOKUP(C45,Códigos!$A$11:$A$415,Códigos!$B$11:$B$415,"Verificar",0) -> NOMBRE 108 | F45: GTFF | G45: 220000 | H45: =+H44+G45 -> 81172600 | I45: Transporte U de A susana
...

Sheet ACUM CAJADIARIO
A1: =+Códigos!$A$1 -> LIBRO DIARIO OFICINA | F1: ARQUEOS DE CAJA | H1: =SUM(H4:H11) -> 807500
A2: ACUMULADOS DE CAJA
A3: =+Códigos!$A$3 -> AÑO: | B3: =+Códigos!$B$3 -> 2025 | F3: DENOMINACIÓN | G3: CANT | H3: TOTAL
A4: DESDE: | B4: =+'INGRESOS A CAJA'!D4 -> 45658 | F4: 100000 | G4: 2 | H4: =+F4*G4 -> 200000
A5: HASTA: | B5: =+'INGRESOS A CAJA'!D5 -> 46022 | F5: 50000 | G5: 12 | H5: =+F5*G5 -> 600000
F6: 20000 | G6: 0 | H6: =+F6*G6 -> 0
A7: ARQUEOS DE CAJA -Efectivo | C7: TOTAL | D7: =+H1 -> 807500 | F7: 10000 | G7: 0 | H7: =+F7*G7 -> 0
C8: SOBRANTE | D8: =IF((D15-D7)<0,-(D15-D7),0) -> 300000 | F8: 5000 | G8: 1 | H8: =+F8*G8 -> 5000
C9: FALTANTE | D9: =IF((D15-D7)>0,(D15-D7),0) -> 0 | F9: 2000 | G9: 1 | H9: =+F9*G9 -> 2000
F10: 1000 | G10: 0 | H10: =+F10*G10 -> 0
A11: CÓDIGO | B11: CONCEPTO | C11: VALOR ACUMULADO POR CÓDIGO | D11: ACUMULADO | F11: MONEDAS | H11: 500
B12: TOTALES EGRESOS | C12: =+C81 -> 633732083 | D12: =+D81 -> 633732083 | F12: =+C12-D12 -> 0 | G12: Control: Diferencia debe ser = 0
B13: TOTAL INGRESOS | C13: =+C119 -> 634239583 | D13: =+D119 -> 634239583 | F13: =+C13-D13 -> 0 | G13: Control: Diferencia debe ser = 0
A14: SALDO INICIAL EN CAJA | C14: 0
A15: SALDO ACTUAL DE CAJA | D15: =C14+C119-C81 -> 507500
A17: EGRESOS
A19: 1 | B19: =_xlfn.XLOOKUP(A19,Códigos!$A$421:$A$483,Códigos!$B$421:$B$483,"Verificar",0) -> Gastos personales | C19: =SUMIF('EGRESOS DE CAJA'!$B$9:$B$5958,A19,'EGRESOS DE CAJA'!$G$9:$G$5958) -> 193927304 | D19: =C19 -> 193927304
A20: 2 | B20: =_xlfn.XLOOKUP(A20,Códigos!$A$421:$A$483,Códigos!$B$421:$B$483,"Verificar",0) -> Pago de Salarios a: | C20: =SUMIF('EGRESOS DE CAJA'!$B$9:$B$5958,A20,'EGRESOS DE CAJA'!$G$9:$G$5958) -> 57460000 | D20: =D19+C20 -> 251387304
A21: 3 | B21: =_xlfn.XLOOKUP(A21,Códigos!$A$421:$A$483,Códigos!$B$421:$B$483,"Verificar",0) -> Pago de Prestaciones sociales a: | C21: =SUMIF('EGRESOS DE CAJA'!$B$9:$B$5958,A21,'EGRESOS DE CAJA'!$G$9:$G$5958) -> 0 | D21: =D20+C21 -> 251387304
A22: 4 | B22: =_xlfn.XLOOKUP(A22,Códigos!$A$421:$A$483,Códigos!$B$421:$B$483,"Verificar",0) -> Pago de Bonificación a: | C22: =SUMIF('EGRESOS DE CAJA'!$B$9:$B$5958,A22,'EGRESOS DE CAJA'!$G$9:$G$5958) -> 0 | D22: =D21+C22 -> 251387304
A23: 5 | B23: =_xlfn.XLOOKUP(A23,Códigos!$A$421:$A$483,Códigos!$B$421:$B$483,"Verificar",0) -> Préstamos por Nómina a: | C23: =SUMIF('EGRESOS DE CAJA'!$B$9:$B$5958,A23,'EGRESOS DE CAJA'!$G$9:$G$5958) -> 12065900 | D23: =D22+C23 -> 263453204
A24: 6 | B24: =_xlfn.XLOOKUP(A24,Códigos!$A$421:$A$483,Códigos!$B$421:$B$483,"Verificar",0) -> Préstamos por Nómina a: | C24: =SUMIF('EGRESOS DE CAJA'!$B$9:$B$5958,A24,'EGRESOS DE CAJA'!$G$9:$G$5958) -> 67737400 | D24: =D23+C24 -> 331190604
A25: 7 | B25: =_xlfn.XLOOKUP(A25,Códigos!$A$421:$A$483,Códigos!$B$421:$B$483,"Verificar",0) -> Pagos de: -Seguridad Social | C25: =SUMIF('EGRESOS DE CAJA'!$B$9:$B$5958,A25,'EGRESOS DE CAJA'!$G$9:$G$5958) -> 27296800 | D25: =D24+C25 -> 358487404
A26: 8 | B26: =_xlfn.XLOOKUP(A26,Códigos!$A$421:$A$483,Códigos!$B$421:$B$483,"Verificar",0) -> Pagos de: -Cuota para alimentos y Manuntención | C26: =SUMIF('EGRESOS DE CAJA'!$B$9:$B$5958,A26,'EGRESOS DE CAJA'!$G$9:$G$5958) -> 43358150 | D26: =D25+C26 -> 401845554
A27: 9 | B27: =_xlfn.XLOOKUP(A27,Códigos!$A$421:$A$483,Códigos!$B$421:$B$483,"Verificar",0) -> Pagos de: -Servicios públicos -OFICINA- | C27: =SUMIF('EGRESOS DE CAJA'!$B$9:$B$5958,A27,'EGRESOS DE CAJA'!$G$9:$G$5958) -> 10779655 | D27: =D26+C27 -> 412625209
A28: 10 | B28: =_xlfn.XLOOKUP(A28,Códigos!$A$421:$A$483,Códigos!$B$421:$B$483,"Verificar",0) -> Pagos de: -Servicios públicos -NIÑAS- | C28: =SUMIF('EGRESOS DE CAJA'!$B$9:$B$5958,A28,'EGRESOS DE CAJA'!$G$9:$G$5958) -> 816300 | D28: =D27+C28 -> 413441509
A29: 11 | B29: =_xlfn.XLOOKUP(A29,Códigos!$A$421:$A$483,Códigos!$B$421:$B$483,"Verificar",0) -> Pagos de: -Servicios Administracion y otros Oficina | C29: =SUMIF('EGRESOS DE CAJA'!$B$9:$B$5958,A29,'EGRESOS DE CAJA'!$G$9:$G$5958) -> 6596185 | D29: =D28+C29 -> 420037694
A30: 12 | B30: =_xlfn.XLOOKUP(A30,Códigos!$A$421:$A$483,Códigos!$B$421:$B$483,"Verificar",0) -> Pagos de: -Celulares | C30: =SUMIF('EGRESOS DE CAJA'!$B$9:$B$5958,A30,'EGRESOS DE CAJA'!$G$9:$G$5958) -> 3595890 | D30: =D29+C30 -> 423633584
A31: 13 | B31: =_xlfn.XLOOKUP(A31,Códigos!$A$421:$A$483,Códigos!$B$421:$B$483,"Verificar",0) -> Pagos de: -Suscripciones | C31: =SUMIF('EGRESOS DE CAJA'!$B$9:$B$5958,A31,'EGRESOS DE CAJA'!$G$9:$G$5958) -> 0 | D31: =D30+C31 -> 423633584
... A78: 60 | B78: =_xlfn.XLOOKUP(A78,Códigos!$A$421:$A$483,Códigos!$B$421:$B$483,"Verificar",0) -> 0 | C78: =SUMIF('EGRESOS DE CAJA'!$B$9:$B$5958,A78,'EGRESOS DE CAJA'!$G$9:$G$5958) -> 0 | D78: =D77+C78 -> 633732083
C79: =SUMIF('EGRESOS DE CAJA'!$B$9:$B$5958,A79,'EGRESOS DE CAJA'!$G$9:$G$5958) -> 0 | D79: =D78+C79 -> 633732083
A81: TOTAL EGRESOS | C81: =SUM(C19:C80) -> 633732083 | D81: =+D79 -> 633732083
A83: INGRESOS
A85: A | B85: =_xlfn.XLOOKUP(A85,Códigos!$A$489:$A$522,Códigos!$B$489:$B$522,"Verificar",0) -> Recibido por: -FACTURAS -GTFF | C85: =SUMIF('INGRESOS A CAJA'!$B$9:$B$4452,A85,'INGRESOS A CAJA'!$F$9:$F$4452) -> 45615800 | D85: =C85 -> 45615800
A86: B | B86: =_xlfn.XLOOKUP(A86,Códigos!$A$489:$A$522,Códigos!$B$489:$B$522,"Verificar",0) -> Recibido por: -Cuentas de cobro -GTFF | C86: =SUMIF('INGRESOS A CAJA'!$B$9:$B$4452,A86,'INGRESOS A CAJA'!$F$9:$F$4452) -> 0 | D86: =D85+C86 -> 45615800
A87: C | B87: =_xlfn.XLOOKUP(A87,Códigos!$A$489:$A$522,Códigos!$B$489:$B$522,"Verificar",0) -> Recibido por: -Cuentas de cobro -DAFF | C87: =SUMIF('INGRESOS A CAJA'!$B$9:$B$4452,A87,'INGRESOS A CAJA'!$F$9:$F$4452) -> 42540000 | D87: =D86+C87 -> 88155800
A88: D | B88: =_xlfn.XLOOKUP(A88,Códigos!$A$489:$A$522,Códigos!$B$489:$B$522,"Verificar",0) -> Recibido por: -Otros ingresos Sin Facturación | C88: =SUMIF('INGRESOS A CAJA'!$B$9:$B$4452,A88,'INGRESOS A CAJA'!$F$9:$F$4452) -> 0 | D88: =D87+C88 -> 88155800
A89: E | B89: =_xlfn.XLOOKUP(A89,Códigos!$A$489:$A$522,Códigos!$B$489:$B$522,"Verificar",0) -> Ingresos Recibidos de terceros para pagos | C89: =SUMIF('INGRESOS A CAJA'!$B$9:$B$4452,A89,'INGRESOS A CAJA'!$F$9:$F$4452) -> 1096000 | D89: =D88+C89 -> 89251800
A90: F | B90: =_xlfn.XLOOKUP(A90,Códigos!$A$489:$A$522,Códigos!$B$489:$B$522,"Verificar",0) -> Recibido por: -Cuentas por Cobrar | C90: =SUMIF('INGRESOS A CAJA'!$B$9:$B$4452,A90,'INGRESOS A CAJA'!$F$9:$F$4452) -> 10076800 | D90: =D89+C90 -> 99328600
A91: G | B91: =_xlfn.XLOOKUP(A91,Códigos!$A$489:$A$522,Códigos!$B$489:$B$522,"Verificar",0) -> Recibido por: -Abono a préstamos por Nómina de: | C91: =SUMIF('INGRESOS A CAJA'!$B$9:$B$4452,A91,'INGRESOS A CAJA'!$F$9:$F$4452) -> 1744200 | D91: =D90+C91 -> 101072800
...

Sheet FACTURACIÓN
A1: =+Códigos!$A$1 -> LIBRO DIARIO OFICINA
A2: RELACIÓN DE FACTURAS | F2: - CONTROL TOPES - DIFERENCIA | G2: =+E331 -> 0 | H2: =+G333 -> 26882000 | I2: DAFF
A3: =+Códigos!$A$3 -> AÑO: | B3: =+Códigos!$B$3 -> 2025 | F3: - CONTROL TOPES - DIFERENCIA | G3: =+E332 -> 0 | H3: =+G334 -> 11454000 | I3: DAFF
A5: DOCUMENTO No. | B5: FECHA DEL DOCUMENTO | C5: CÓDIGO DEL CLIENTE | D5: APELLIDOS Y NOMBRES o RAZÓN SOCIAL DEL CLIENTE o TERCERO | E5: HACE RET FTE | F5: DETALLE | G5: VALOR BRUTO DEL DOCUMENTO | H5: I V A | I5: VALOR TOTAL DEL DOCUMENTO | J5: RETENCIÓN EN LA FUENTE | K5: SALDO A PAGAR | L5: ABONOS | M5: DESCUENTOS | N5: SALDO POR COBRAR AL CLIENTE | O5: SALDO POR PAGAR A CARGO DE LA OFICINA | P5: FORMA DE PAGO | Q5: FECHA DE PAGO | R5: OBSERVACIONES
A8: FACTURAS -GERMÁN TULIO FERNÁNDEZ FERNÁNDEZ-
A9: GTFF-163 | B9: 45827 | C9: 10 | D9: =_xlfn.XLOOKUP(C9,Códigos!$A$11:$A$415,Códigos!$B$11:$B$415,"Verificar",0) -> NOMBRE 80 | E9: SI | F9: Asesoría tributaria año gravable 2024 | G9: 7553000 | H9: =+G9*19% -> 1435070 | I9: =+G9+H9 -> 8988070 | J9: =+G9*0.11 -> 830830 | K9: =+I9-J9 -> 8157240 | L9: 8157240 | M9: 0 | N9: =IF(+(K9-L9-M9)<0,0,(K9-L9-M9)) -> 0 | O9: =IF(+(K9-L9-M9)>0,0,(K9-L9-M9)) -> 0 | P9: Cheque 0231402-4 | Q9: 45828
A10: GTFF-164 | B10: 45827 | C10: 19 | D10: =_xlfn.XLOOKUP(C10,Códigos!$A$11:$A$415,Códigos!$B$11:$B$415,"Verificar",0) -> NOMBRE 164 | E10: SI | F10: Asesoría tributaria año gravable 2024 | G10: 11025000 | H10: =+G10*19% -> 2094750 | I10: =+G10+H10 -> 13119750 | J10: =IF(E10="SI",G10*11%,0) -> 1212750 | K10: =+I10-J10 -> 11907000 | L10: 11907000 | M10: 0 | N10: =IF(+(K10-L10-M10)<0,0,(K10-L10-M10)) -> 0 | O10: =IF(+(K10-L10-M10)>0,0,(K10-L10-M10)) -> 0 | P10: Cheque 0231402-4 | Q10: 45828
A11: GTFF-165 | B11: 45827 | C11: 28 | D11: =_xlfn.XLOOKUP(C11,Códigos!$A$11:$A$415,Códigos!$B$11:$B$415,"Verificar",0) -> NOMBRE 180 | E11: SI | F11: Asesoría tributaria año gravable 2024 | G11: 11025000 | H11: =+G11*19% -> 2094750 | I11: =+G11+H11 -> 13119750 | J11: =+G11*0.11 -> 1212750 | K11: =+I11-J11 -> 11907000 | L11: 11907000 | M11: 0 | N11: =IF(+(K11-L11-M11)<0,0,(K11-L11-M11)) -> 0 | O11: =IF(+(K11-L11-M11)>0,0,(K11-L11-M11)) -> 0 | P11: Cheque 0231402-4 | Q11: 45828
A12: GTFF-160 | D12: =_xlfn.XLOOKUP(C12,Códigos!$A$11:$A$415,Códigos!$B$11:$B$415,"Verificar",0) -> 0 | E12: SI | F12: Asesoría tributaria año gravable 2024 | H12: =+G12*19% -> 0 | I12: =+G12+H12 -> 0 | J12: =IF(E12="SI",G12*11%,0) -> 0 | K12: =+I12-J12 -> 0 | M12: 0 | N12: =IF(+(K12-L12-M12)<0,0,(K12-L12-M12)) -> 0 | O12: =IF(+(K12-L12-M12)>0,0,(K12-L12-M12)) -> 0
A13: GTFF-160 | D13: =_xlfn.XLOOKUP(C13,Códigos!$A$11:$A$415,Códigos!$B$11:$B$415,"Verificar",0) -> 0 | E13: SI | F13: Asesoría tributaria año gravable 2024 | H13: =+G13*19% -> 0 | I13: =+G13+H13 -> 0 | J13: =IF(E13="SI",G13*11%,0) -> 0 | K13: =+I13-J13 -> 0 | M13: 0 | N13: =IF(+(K13-L13-M13)<0,0,(K13-L13-M13)) -> 0 | O13: =IF(+(K13-L13-M13)>0,0,(K13-L13-M13)) -> 0
A14: GTFF-160 | D14: =_xlfn.XLOOKUP(C14,Códigos!$A$11:$A$415,Códigos!$B$11:$B$415,"Verificar",0) -> 0 | E14: SI | F14: Asesoría tributaria año gravable 2024 | H14: =+G14*19% -> 0 | I14: =+G14+H14 -> 0 | J14: =IF(E14="SI",G14*11%,0) -> 0 | K14: =+I14-J14 -> 0 | M14: 0 | N14: =IF(+(K14-L14-M14)<0,0,(K14-L14-M14)) -> 0 | O14: =IF(+(K14-L14-M14)>0,0,(K14-L14-M14)) -> 0
A15: GTFF-160 | D15: =_xlfn.XLOOKUP(C15,Códigos!$A$11:$A$415,Códigos!$B$11:$B$415,"Verificar",0) -> 0 | E15: SI | F15: Asesoría tributaria año gravable 2024 | H15: =+G15*19% -> 0 | I15: =+G15+H15 -> 0 | J15: =IF(E15="SI",G15*11%,0) -> 0 | K15: =+I15-J15 -> 0 | M15: 0 | N15: =IF(+(K15-L15-M15)<0,0,(K15-L15-M15)) -> 0 | O15: =IF(+(K15-L15-M15)>0,0,(K15-L15-M15)) -> 0
A16: GTFF-160 | D16: =_xlfn.XLOOKUP(C16,Códigos!$A$11:$A$415,Códigos!$B$11:$B$415,"Verificar",0) -> 0 | E16: SI | F16: Asesoría tributaria año gravable 2024 | H16: =+G16*19% -> 0 | I16: =+G16+H16 -> 0 | J16: =IF(E16="SI",G16*11%,0) -> 0 | K16: =+I16-J16 -> 0 | M16: 0 | N16: =IF(+(K16-L16-M16)<0,0,(K16-L16-M16)) -> 0 | O16: =IF(+(K16-L16-M16)>0,0,(K16-L16-M16)) -> 0
A17: GTFF-160 | D17: =_xlfn.XLOOKUP(C17,Códigos!$A$11:$A$415,Códigos!$B$11:$B$415,"Verificar",0) -> 0 | E17: SI | F17: Asesoría tributaria año gravable 2024 | H17: =+G17*19% -> 0 | I17: =+G17+H17 -> 0 | J17: =IF(E17="SI",G17*11%,0) -> 0 | K17: =+I17-J17 -> 0 | M17: 0 | N17: =IF(+(K17-L17-M17)<0,0,(K17-L17-M17)) -> 0 | O17: =IF(+(K17-L17-M17)>0,0,(K17-L17-M17)) -> 0
A18: GTFF-160 | D18: =_xlfn.XLOOKUP(C18,Códigos!$A$11:$A$415,Códigos!$B$11:$B$415,"Verificar",0) -> 0 | E18: SI | F18: Asesoría tributaria año gravable 2024 | H18: =+G18*19% -> 0 | I18: =+G18+H18 -> 0 | J18: =IF(E18="SI",G18*11%,0) -> 0 | K18: =+I18-J18 -> 0 | M18: 0 | N18: =IF(+(K18-L18-M18)<0,0,(K18-L18-M18)) -> 0 | O18: =IF(+(K18-L18-M18)>0,0,(K18-L18-M18)) -> 0
A19: GTFF-160 | D19: =_xlfn.XLOOKUP(C19,Códigos!$A$11:$A$415,Códigos!$B$11:$B$415,"Verificar",0) -> 0 | E19: SI | F19: Asesoría tributaria año gravable 2024 | H19: =+G19*19% -> 0 | I19: =+G19+H19 -> 0 | J19: =IF(E19="SI",G19*11%,0) -> 0 | K19: =+I19-J19 -> 0 | M19: 0 | N19: =IF(+(K19-L19-M19)<0,0,(K19-L19-M19)) -> 0 | O19: =IF(+(K19-L19-M19)>0,0,(K19-L19-M19)) -> 0
A20: GTFF-160 | D20: =_xlfn.XLOOKUP(C20,Códigos!$A$11:$A$415,Códigos!$B$11:$B$415,"Verificar",0) -> 0 | E20: SI | F20: Asesoría tributaria año gravable 2024 | H20: =+G20*19% -> 0 | I20: =+G20+H20 -> 0 | J20: =IF(E20="SI",G20*11%,0) -> 0 | K20: =+I20-J20 -> 0 | M20: 0 | N20: =IF(+(K20-L20-M20)<0,0,(K20-L20-M20)) -> 0 | O20: =IF(+(K20-L20-M20)>0,0,(K20-L20-M20)) -> 0
A21: GTFF-160 | D21: =_xlfn.XLOOKUP(C21,Códigos!$A$11:$A$415,Códigos!$B$11:$B$415,"Verificar",0) -> 0 | E21: SI | F21: Asesoría tributaria año gravable 2024 | H21: =+G21*19% -> 0 | I21: =+G21+H21 -> 0 | J21: =IF(E21="SI",G21*11%,0) -> 0 | K21: =+I21-J21 -> 0 | M21: 0 | N21: =IF(+(K21-L21-M21)<0,0,(K21-L21-M21)) -> 0 | O21: =IF(+(K21-L21-M21)>0,0,(K21-L21-M21)) -> 0
A22: GTFF-160 | D22: =_xlfn.XLOOKUP(C22,Códigos!$A$11:$A$415,Códigos!$B$11:$B$415,"Verificar",0) -> 0 | E22: SI | F22: Asesoría tributaria año gravable 2024 | H22: =+G22*19% -> 0 | I22: =+G22+H22 -> 0 | J22: =IF(E22="SI",G22*11%,0) -> 0 | K22: =+I22-J22 -> 0 | M22: 0 | N22: =IF(+(K22-L22-M22)<0,0,(K22-L22-M22)) -> 0 | O22: =IF(+(K22-L22-M22)>0,0,(K22-L22-M22)) -> 0
A23: GTFF-160 | D23: =_xlfn.XLOOKUP(C23,Códigos!$A$11:$A$415,Códigos!$B$11:$B$415,"Verificar",0) -> 0 | E23: SI | F23: Asesoría tributaria año gravable 2024 | H23: =+G23*19% -> 0 | I23: =+G23+H23 -> 0 | J23: =IF(E23="SI",G23*11%,0) -> 0 | K23: =+I23-J23 -> 0 | M23: 0 | N23: =IF(+(K23-L23-M23)<0,0,(K23-L23-M23)) -> 0 | O23: =IF(+(K23-L23-M23)>0,0,(K23-L23-M23)) -> 0
... A36: GTFF-160 | D36: =_xlfn.XLOOKUP(C36,Códigos!$A$11:$A$415,Códigos!$B$11:$B$415,"Verificar",0) -> 0 | E36: NO | F36: Asesoría tributaria año gravable 2024 | H36: =+G36*19% -> 0 | I36: =+G36+H36 -> 0 | J36: =IF(E36="SI",G36*11%,0) -> 0 | K36: =+I36-J36 -> 0 | M36: 0 | N36: =IF(+(K36-L36-M36)<0,0,(K36-L36-M36)) -> 0 | O36: =IF(+(K36-L36-M36)>0,0,(K36-L36-M36)) -> 0
A37: GTFF-160 | D37: =_xlfn.XLOOKUP(C37,Códigos!$A$11:$A$415,Códigos!$B$11:$B$415,"Verificar",0) -> 0 | E37: NO | G37: 0 | H37: =+G37*19% -> 0 | I37: =+G37+H37 -> 0 | J37: =IF(E37="SI",G37*11%,0) -> 0 | K37: =+I37-J37 -> 0 | M37: 0 | N37: =IF(+(K37-L37-M37)<0,0,(K37-L37-M37)) -> 0 | O37: =IF(+(K37-L37-M37)>0,0,(K37-L37-M37)) -> 0
A38: GTFF-160 | D38: =_xlfn.XLOOKUP(C38,Códigos!$A$11:$A$415,Códigos!$B$11:$B$415,"Verificar",0) -> 0 | E38: NO | G38: 0 | H38: =+G38*19% -> 0 | I38: =+G38+H38 -> 0 | J38: =IF(E38="SI",G38*11%,0) -> 0 | K38: =+I38-J38 -> 0 | M38: 0 | N38: =IF(+(K38-L38-M38)<0,0,(K38-L38-M38)) -> 0 | O38: =IF(+(K38-L38-M38)>0,0,(K38-L38-M38)) -> 0
A39: GTFF-160 | D39: =_xlfn.XLOOKUP(C39,Códigos!$A$11:$A$415,Códigos!$B$11:$B$415,"Verificar",0) -> 0 | E39: NO | G39: 0 | H39: =+G39*19% -> 0 | I39: =+G39+H39 -> 0 | J39: =IF(E39="SI",G39*11%,0) -> 0 | K39: =+I39-J39 -> 0 | M39: 0 | N39: =IF(+(K39-L39-M39)<0,0,(K39-L39-M39)) -> 0 | O39: =IF(+(K39-L39-M39)>0,0,(K39-L39-M39)) -> 0
A40: GTFF-160 | D40: =_xlfn.XLOOKUP(C40,Códigos!$A$11:$A$415,Códigos!$B$11:$B$415,"Verificar",0) -> 0 | E40: NO | G40: 0 | H40: =+G40*19% -> 0 | I40: =+G40+H40 -> 0 | J40: =IF(E40="SI",G40*11%,0) -> 0 | K40: =+I40-J40 -> 0 | M40: 0 | N40: =IF(+(K40-L40-M40)<0,0,(K40-L40-M40)) -> 0 | O40: =IF(+(K40-L40-M40)>0,0,(K40-L40-M40)) -> 0
A41: GTFF-160 | D41: =_xlfn.XLOOKUP(C41,Códigos!$A$11:$A$415,Códigos!$B$11:$B$415,"Verificar",0) -> 0 | E41: NO | G41: 0 | H41: =+G41*19% -> 0 | I41: =+G41+H41 -> 0 | J41: =IF(E41="SI",G41*11%,0) -> 0 | K41: =+I41-J41 -> 0 | M41: 0 | N41: =IF(+(K41-L41-M41)<0,0,(K41-L41-M41)) -> 0 | O41: =IF(+(K41-L41-M41)>0,0,(K41-L41-M41)) -> 0
A42: GTFF-160 | D42: =_xlfn.XLOOKUP(C42,Códigos!$A$11:$A$415,Códigos!$B$11:$B$415,"Verificar",0) -> 0 | E42: NO | G42: 0 | H42: =+G42*19% -> 0 | I42: =+G42+H42 -> 0 | J42: =IF(E42="SI",G42*11%,0) -> 0 | K42: =+I42-J42 -> 0 | M42: 0 | N42: =IF(+(K42-L42-M42)<0,0,(K42-L42-M42)) -> 0 | O42: =IF(+(K42-L42-M42)>0,0,(K42-L42-M42)) -> 0
A43: GTFF-160 | D43: =_xlfn.XLOOKUP(C43,Códigos!$A$11:$A$415,Códigos!$B$11:$B$415,"Verificar",0) -> 0 | E43: NO | G43: 0 | H43: =+G43*19% -> 0 | I43: =+G43+H43 -> 0 | J43: =IF(E43="SI",G43*11%,0) -> 0 | K43: =+I43-J43 -> 0 | M43: 0 | N43: =IF(+(K43-L43-M43)<0,0,(K43-L43-M43)) -> 0 | O43: =IF(+(K43-L43-M43)>0,0,(K43-L43-M43)) -> 0
A44: GTFF-160 | D44: =_xlfn.XLOOKUP(C44,Códigos!$A$11:$A$415,Códigos!$B$11:$B$415,"Verificar",0) -> 0 | E44: NO | G44: 0 | H44: =+G44*19% -> 0 | I44: =+G44+H44 -> 0 | J44: =IF(E44="SI",G44*11%,0) -> 0 | K44: =+I44-J44 -> 0 | M44: 0 | N44: =IF(+(K44-L44-M44)<0,0,(K44-L44-M44)) -> 0 | O44: =IF(+(K44-L44-M44)>0,0,(K44-L44-M44)) -> 0
A45: GTFF-160 | D45: =_xlfn.XLOOKUP(C45,Códigos!$A$11:$A$415,Códigos!$B$11:$B$415,"Verificar",0) -> 0 | E45: NO | G45: 0 | H45: =+G45*19% -> 0 | I45: =+G45+H45 -> 0 | J45: =IF(E45="SI",G45*11%,0) -> 0 | K45: =+I45-J45 -> 0 | L45: 0 | M45: 0 | N45: =IF(+(K45-L45-M45)<0,0,(K45-L45-M45)) -> 0 | O45: =IF(+(K45-L45-M45)>0,0,(K45-L45-M45)) -> 0
A46: GTFF-160 | D46: =_xlfn.XLOOKUP(C46,Códigos!$A$11:$A$415,Códigos!$B$11:$B$415,"Verificar",0) -> 0 | E46: NO | G46: 0 | H46: =+G46*19% -> 0 | I46: =+G46+H46 -> 0 | J46: =IF(E46="SI",G46*11%,0) -> 0 | K46: =+I46-J46 -> 0 | L46: 0 | M46: 0 | N46: =IF(+(K46-L46-M46)<0,0,(K46-L46-M46)) -> 0 | O46: =IF(+(K46-L46-M46)>0,0,(K46-L46-M46)) -> 0
A47: GTFF-160 | D47: =_xlfn.XLOOKUP(C47,Códigos!$A$11:$A$415,Códigos!$B$11:$B$415,"Verificar",0) -> 0 | E47: NO | G47: 0 | H47: =+G47*19% -> 0 | I47: =+G47+H47 -> 0 | J47: =IF(E47="SI",G47*11%,0) -> 0 | K47: =+I47-J47 -> 0 | L47: 0 | M47: 0 | N47: =IF(+(K47-L47-M47)<0,0,(K47-L47-M47)) -> 0 | O47: =IF(+(K47-L47-M47)>0,0,(K47-L47-M47)) -> 0
A48: GTFF-160 | D48: =_xlfn.XLOOKUP(C48,Códigos!$A$11:$A$415,Códigos!$B$11:$B$415,"Verificar",0) -> 0 | E48: NO | G48: 0 | H48: =+G48*19% -> 0 | I48: =+G48+H48 -> 0 | J48: =IF(E48="SI",G48*11%,0) -> 0 | K48: =+I48-J48 -> 0 | L48: 0 | M48: 0 | N48: =IF(+(K48-L48-M48)<0,0,(K48-L48-M48)) -> 0 | O48: =IF(+(K48-L48-M48)>0,0,(K48-L48-M48)) -> 0
A49: GTFF-160 | D49: =_xlfn.XLOOKUP(C49,Códigos!$A$11:$A$415,Códigos!$B$11:$B$415,"Verificar",0) -> 0 | E49: NO | G49: 0 | H49: =+G49*19% -> 0 | I49: =+G49+H49 -> 0 | J49: =IF(E49="SI",G49*11%,0) -> 0 | K49: =+I49-J49 -> 0 | L49: 0 | M49: 0 | N49: =IF(+(K49-L49-M49)<0,0,(K49-L49-M49)) -> 0 | O49: =IF(+(K49-L49-M49)>0,0,(K49-L49-M49)) -> 0
A50: GTFF-160 | D50: =_xlfn.XLOOKUP(C50,Códigos!$A$11:$A$415,Códigos!$B$11:$B$415,"Verificar",0) -> 0 | E50: NO | G50: 0 | H50: =+G50*19% -> 0 | I50: =+G50+H50 -> 0 | J50: =IF(E50="SI",G50*11%,0) -> 0 | K50: =+I50-J50 -> 0 | L50: 0 | M50: 0 | N50: =IF(+(K50-L50-M50)<0,0,(K50-L50-M50)) -> 0 | O50: =IF(+(K50-L50-M50)>0,0,(K50-L50-M50)) -> 0
A51: GTFF-160 | D51: =_xlfn.XLOOKUP(C51,Códigos!$A$11:$A$415,Códigos!$B$11:$B$415,"Verificar",0) -> 0 | G51: 0 | H51: =+G51*19% -> 0 | I51: =+G51+H51 -> 0 | J51: =IF(E51="SI",G51*11%,0) -> 0 | K51: =+I51-J51 -> 0 | L51: 0 | M51: 0 | N51: =IF(+(K51-L51-M51)<0,0,(K51-L51-M51)) -> 0 | O51: =IF(+(K51-L51-M51)>0,0,(K51-L51-M51)) -> 0
A52: GTFF- | D52: =_xlfn.XLOOKUP(C52,Códigos!$A$11:$A$415,Códigos!$B$11:$B$415,"Verificar",0) -> 0 | G52: 0 | H52: =+G52*19% -> 0 | I52: =+G52+H52 -> 0 | J52: =IF(E52="SI",G52*11%,0) -> 0 | K52: =+I52-J52 -> 0 | L52: 0 | M52: 0 | N52: =IF(+(K52-L52-M52)<0,0,(K52-L52-M52)) -> 0 | O52: =IF(+(K52-L52-M52)>0,0,(K52-L52-M52)) -> 0
A53: GTFF- | D53: =_xlfn.XLOOKUP(C53,Códigos!$A$11:$A$415,Códigos!$B$11:$B$415,"Verificar",0) -> 0 | G53: 0 | H53: =+G53*19% -> 0 | I53: =+G53+H53 -> 0 | J53: =IF(E53="SI",G53*11%,0) -> 0 | K53: =+I53-J53 -> 0 | L53: 0 | M53: 0 | N53: =IF(+(K53-L53-M53)<0,0,(K53-L53-M53)) -> 0 | O53: =IF(+(K53-L53-M53)>0,0,(K53-L53-M53)) -> 0
