Workbook
Name _Toc464338185: 'TABLA RetFte'!$A$16

Sheet Grupos Familiares
A2: GRUPOS FAMILIARES | L2: RETENCIÓN EN LA FUENTE
A3: PRESUPUESTO DE COBROS
A4: AÑO GRAVABLE 2024 | O4: RETENCIÓN FUENTE -Honorarios- | P4: UVT 2025
B5: =+A583 -> GRAN TOTAL | C5: =+C583 -> 0 | D5: =+D583 -> 0 | E5: =+E583 -> 0 | F5: =+F583 -> 0 | G5: =+G583 -> 0 | H5: =+H583 -> 0 | I5: =+I583 -> 0 | O5: 0.11 | P5: 49799
A6: No. | B6: APELLIDOS Y NOMBRES o RAZÓN SOCIAL | C6: VALOR FACTURA | D6: I V A | E6: RETENCIÓN EN LA FUENTE | F6: VALOR FACTURA antes de RTE FTE | G6: VALOR TOTAL NETO DE LA FACTURA | H6: VALOR CUENTA DE COBRO | I6: VALOR NETO TOTAL FRAS + C DE C | J6: OBSERVACIONES | L6: SEGURIDAD SOCIAL | M6: Ingreso Base RetFte | N6: AGENTE RETENEDOR | O6: RETENCIÓN EN LA FUENTE | P6: Vr Ingreso Base RetFte EN UVT
L7: =12.5%+16% -> 0.285
A8: FAMILIA RESTREPO POSADA
A11: 1
A12: SUB TOTAL | L12: =+C12*$L$7 -> 0 | M12: =+C12-L12*0 -> 0 | N12: N | O12: =IF(N12="S",M12*$O$5,"NO RETENCIÓN") -> NO RETENCIÓN | P12: =+M12/$P$5 -> 0
A15: 1
A16: =A15+1 -> 2
A17: SUB TOTAL | L17: =+C17*$L$7 -> 0 | M17: =+C17-L17*0 -> 0 | N17: S | O17: =IF(N17="S",M17*$O$5,"NO RETENCIÓN") -> 0 | P17: =+M17/$P$5 -> 0
A21: 1
A22: SUB TOTAL | L22: =+C22*$L$7 -> 0 | M22: =+C22-L22*0 -> 0 | N22: N | O22: =IF(N22="S",M22*$O$5,"NO RETENCIÓN") -> NO RETENCIÓN | P22: =+M22/$P$5 -> 0
A25: =A21+1 -> 2
A26: SUB TOTAL | L26: =+C26*$L$7 -> 0 | M26: =+C26-L26*0 -> 0 | N26: N | O26: =IF(N26="S",M26*$O$5,"NO RETENCIÓN") -> NO RETENCIÓN | P26: =+M26/$P$5 -> 0
A29: =A25+1 -> 3
A30: =A29+1 -> 4
A31: SUB TOTAL | L31: =+C31*$L$7 -> 0 | M31: =+C31-L31*0 -> 0 | N31: S | O31: =IF(N31="S",M31*$O$5,"NO RETENCIÓN") -> 0 | P31: =+M31/$P$5 -> 0
A33: TOTAL DOÑA SILVIA ELENA
A37: 1
A38: =A37+1 -> 2
A39: SUB TOTAL | L39: =+C39*$L$7 -> 0 | M39: =+C39-L39*0 -> 0 | N39: S | O39: =IF(N39="S",M39*$O$5,"NO RETENCIÓN") -> 0 | P39: =+M39/$P$5 -> 0
A42: 1
A43: =A42+1 -> 2
A44: =+A43+1 -> 3
A45: SUB TOTAL | L45: =+C45*$L$7 -> 0 | M45: =+C45-L45*0 -> 0 | N45: N | O45: =IF(N45="S",M45*$O$5,"NO RETENCIÓN") -> NO RETENCIÓN | P45: =+M45/$P$5 -> 0
A48: =+A44+1 -> 4
A49: SUB TOTAL | L49: =+C49*$L$7 -> 0 | M49: =+C49-L49*0 -> 0 | N49: N | O49: =IF(N49="S",M49*$O$5,"NO RETENCIÓN") -> NO RETENCIÓN | P49: =+M49/$P$5 -> 0
A53: 1
A54: =+A53+1 -> 2
A55: =A54+1 -> 3
A56: =+A55+1 -> 4
A57: SUB TOTAL | L57: =+C57*$L$7 -> 0 | M57: =+C57-L57*0 -> 0 | N57: S | O57: =IF(N57="S",M57*$O$5,"NO RETENCIÓN") -> 0 | P57: =+M57/$P$5 -> 0
A60: =A58+1 -> 1
A61: =+A60+1 -> 2
A62: =+A61+1 -> 3
A63: =A62+1 -> 4
A64: =A63+1 -> 5
A65: SUB TOTAL | L65: =+C65*$L$7 -> 0 | M65: =+C65-L65*0 -> 0 | N65: S | O65: =IF(N65="S",M65*$O$5,"NO RETENCIÓN") -> 0 | P65: =+M65/$P$5 -> 0
...

Sheet Facturas
A2: =+'Grupos Familiares'!$A$3 -> PRESUPUESTO DE COBROS | Q2: Mínima Mvto | S2: Mínima 1° Vez | U2: PARA CALCULAR EL VALOR A COBRAR POR EL PRESENTE AÑO | AO2: IPC 2024 | AP2: Mínima Mvto -año anterior- | AQ2: Mínima 1° Vez -Año anterior-
A3: FACTURACIÓN ELECTRÓNICA | Q3: =ROUND(AP3*(100%+$AO$3),-4) -> 230000 | S3: =ROUND(AQ3*(100%+$AO$3),-4) -> 370000 | AO3: 0.052 | AP3: 220000 | AQ3: 350000
A4: =+'Grupos Familiares'!$A$4 -> AÑO GRAVABLE 2024 | F4: VALORES A FACTURAR -PRESENTE AÑO- | U4: PRESUPUESTOS DE COBRO: | Y4: =+$A$3 -> FACTURACIÓN ELECTRÓNICA | AO4: Vr Incrementado | AP4: =(AP3*(100%+$AO$3)) -> 231440 | AQ4: =(AQ3*(100%+$AO$3)) -> 368200
A5: PERSONAS NATURALES Y PERSONAS JURÍDICAS | G5: 0.19 | I5: 0.11 | U5: IPC | V5: =+AO3 -> 0.052 | X5: 0.5 | Z5: =75%+80%*0 -> 0.75 | AB5: 0.15 | AD5: 0.2 | AF5: 0.1 | AH5: 0.2 | AJ5: 0.3
A6: No. | B6: APELLIDOS Y NOMBRES o RAZÓN SOCIAL | C6: CÓDIGO | D6: NIT No. | E6: D. V. | F6: VALOR BRUTO A ELABORAR LA FACTURA | G6: I V A | H6: AGENTE RETENEDOR | I6: RETENCIÓN EN LA FUENTE | J6: VALOR FACTURA antes de RTE FTE | K6: VALOR A PAGAR NETO DE LA FACTURA | L6: VoBo ELABORAR Fra. | M6: FACTURA No. | N6: MEDIO | O6: FECHA | P6: ESTADO | Q6: VALOR CUENTA DE COBRO -POR PRÉSTAMOS- | R6: CUENTA DE COBRO No. | S6: OBSERVACIONES | U6: SI o NO | V6: VALOR DECLARACIÓN RENTA | W6: SI o NO | X6: VALOR DECLARACIÓN I AL P 2023 | Y6: SI o NO | Z6: VALOR MEDIOS MAGNÉTICOS | AA6: SI o NO | AB6: EXÓGENA MPIO MEDELLÍN | AC6: SI o NO | AD6: REG ÚNICO de BENEFICIARIOS | AE6: SI o NO | AF6: VALOR FORMATO 2516 CONSERVAR | AG6: SI o NO | AH6: VALOR FORMATO 2516 TRANSMITIR | AI6: SI o NO | AJ6: VALOR DECLARACIÓN ACTIVOS EN EL EXTERIOR | AK6: VALOR OTRAS ASESORÍAS | AL6: PRÉSTAMOS | AM6: TOTAL PRESUPUESTADO | AO6: FACTURAS y C de C
A8: PERSONAS NATURALES
A9: 1 | B9: NOMBRE 1 | C9: =_xlfn.XLOOKUP(B9,Códigos!$B$8:$B$406,Códigos!$A$8:$A$406,"Verificar",0) -> 41 | D9: =_xlfn.XLOOKUP(B9,'Consolidado Cobros'!$B$10:$B$268,'Consolidado Cobros'!$C$10:$C$268,"Verificar",0) -> 22126399 | E9: =IF((MOD((VALUE(MID(TEXT(D9,"000000000000000"),15,1))*3+VALUE(MID(TEXT(D9,"000000000000000"),14,1))*7+VALUE(MID(TEXT(D9,"000000000000000"),13,1))*13+VALUE(MID(TEXT(D9,"000000000000000"),12,1))*17+VALUE(MID(TEXT(D9,"000000000000000"),11,1))*19+VALUE(MID(TEXT(D9,"000000000000000"),10,1))*23+VALUE(MID(TEXT(D9,"000000000000000"),9,1))*29+VALUE(MID(TEXT(D9,"000000000000000"),8,1))*37+VALUE(MID(TEXT(D9,"000000000000000"),7,1))*41+VALUE(MID(TEXT(D9,"000000000000000"),6,1))*43+VALUE(MID(TEXT(D9,"000000000000000"),5,1))*47+VALUE(MID(TEXT(D9,"000000000000000"),4,1))*53+VALUE(MID(TEXT(D9,"000000000000000"),3,1))*59+VALUE(MID(TEXT(D9,"000000000000000"),2,1))*67+VALUE(MID(TEXT(D9,"000000000000000"),1,1))*71),11))=0,0,IF((MOD((VALUE(MID(TEXT(D9,"000000000000000"),15,1))*3+VALUE(MID(TEXT(D9,"000000000000000"),14,1))*7+VALUE(MID(TEXT(D9,"000000000000000"),13,1))*13+VALUE(MID(TEXT(D9,"000000000000000"),12,1))*17+VALUE(MID(TEXT(D9,"000000000000000"),11,1))*19+VALUE(MID(TEXT(D9,"000000000000000"),10,1))*23+VALUE(MID(TEXT(D9,"000000000000000"),9,1))*29+VALUE(MID(TEXT(D9,"000000000000000"),8,1))*37+VALUE(MID(TEXT(D9,"000000000000000"),7,1))*41+VALUE(MID(TEXT(D9,"000000000000000"),6,1))*43+VALUE(MID(TEXT(D9,"000000000000000"),5,1))*47+VALUE(MID(TEXT(D9,"000000000000000"),4,1))*53+VALUE(MID(TEXT(D9,"000000000000000"),3,1))*59+VALUE(MID(TEXT(D9,"000000000000000"),2,1))*67+VALUE(MID(TEXT(D9,"000000000000000"),1,1))*71),11))=1,1,11-(MOD((VALUE(MID(TEXT(D9,"000000000000000"),15,1))*3+VALUE(MID(TEXT(D9,"000000000000000"),14,1))*7+VALUE(MID(TEXT(D9,"000000000000000"),13,1))*13+VALUE(MID(TEXT(D9,"000000000000000"),12,1))*17+VALUE(MID(TEXT(D9,"000000000000000"),11,1))*19+VALUE(MID(TEXT(D9,"000000000000000"),10,1))*23+VALUE(MID(TEXT(D9,"000000000000000"),9,1))*29+VALUE(MID(TEXT(D9,"000000000000000"),8,1))*37+VALUE(MID(TEXT(D9,"000000000000000"),7,1))*41+VALUE(MID(TEXT(D9,"000000000000000"),6,1))*43+VALUE(MID(TEXT(D9,"000000000000000"),5,1))*47+VALUE(MID(TEXT(D9,"000000000000000"),4,1))*53+VALUE(MID(TEXT(D9,"000000000000000"),3,1))*59+VALUE(MID(TEXT(D9,"000000000000000"),2,1))*67+VALUE(MID(TEXT(D9,"000000000000000"),1,1))*71),11)))) -> 5 | F9: =+AM9 -> 870000 | G9: =+F9*$G$5 -> 165300 | H9: S | I9: =IF(H9="S",-F9*$I$5,"NO RETENCIÓN") -> -95700 | J9: =+F9+G9 -> 1035300 | K9: =SUM(F9:I9) -> 939600 | Q9: =+AL9 -> 0 | U9: SI | V9: =ROUND(IF(U9="SI",SUMIF('Facturas año anterior'!$B$8:$B$81,B9,'Facturas año anterior'!$V$8:$V$81)*(100%+$V$5),0),-3)+ROUND(IF(U9="SI",SUMIF('C de C año anterior'!$B$8:$B$210,B9,'C de C año anterior'!$Q$8:$Q$210)*(100%+$V$5),0),-3) -> 871000 | X9: =ROUND(IF(W9="SI",V9*$X$5,0),-3) -> 0 | Z9: =ROUND(IF(Y9="SI",V9*$Z$5,0),-3) -> 0 | AB9: =ROUND(IF(AA9="SI",V9*$AB$5,0),-3) -> 0 | AD9: =ROUND(IF(AC9="SI",V9*$AD$5,0),-3) -> 0 | AF9: =ROUND(IF(AE9="SI",V9*$AF$5,0),-3) -> 0 | AH9: =ROUND(IF(AG9="SI",V9*$AH$5,0),-3) -> 0 | AJ9: =IF(AI9="SI",V9*$AJ$5,0) -> 0 | AK9: =SUMIF('Otras Asesorías y Préstamos'!$B$7:$B$242,B9,'Otras Asesorías y Préstamos'!$F$7:$F$242) -> 0 | AL9: =SUMIF('Otras Asesorías y Préstamos'!$B$7:$B$242,B9,'Otras Asesorías y Préstamos'!$V$7:$V$242) -> 0 | AM9: =ROUND(SUM(V9:AK9),-4) -> 870000
A10: =+A9+1 -> 2 | B10: NOMBRE 2 | C10: =_xlfn.XLOOKUP(B10,Códigos!$B$8:$B$406,Códigos!$A$8:$A$406,"Verificar",0) -> 346 | D10: =_xlfn.XLOOKUP(B10,'Consolidado Cobros'!$B$10:$B$268,'Consolidado Cobros'!$C$10:$C$268,"Verificar",0) -> 71581755 | E10: =IF((MOD((VALUE(MID(TEXT(D10,"000000000000000"),15,1))*3+VALUE(MID(TEXT(D10,"000000000000000"),14,1))*7+VALUE(MID(TEXT(D10,"000000000000000"),13,1))*13+VALUE(MID(TEXT(D10,"000000000000000"),12,1))*17+VALUE(MID(TEXT(D10,"000000000000000"),11,1))*19+VALUE(MID(TEXT(D10,"000000000000000"),10,1))*23+VALUE(MID(TEXT(D10,"000000000000000"),9,1))*29+VALUE(MID(TEXT(D10,"000000000000000"),8,1))*37+VALUE(MID(TEXT(D10,"000000000000000"),7,1))*41+VALUE(MID(TEXT(D10,"000000000000000"),6,1))*43+VALUE(MID(TEXT(D10,"000000000000000"),5,1))*47+VALUE(MID(TEXT(D10,"000000000000000"),4,1))*53+VALUE(MID(TEXT(D10,"000000000000000"),3,1))*59+VALUE(MID(TEXT(D10,"000000000000000"),2,1))*67+VALUE(MID(TEXT(D10,"000000000000000"),1,1))*71),11))=0,0,IF((MOD((VALUE(MID(TEXT(D10,"000000000000000"),15,1))*3+VALUE(MID(TEXT(D10,"000000000000000"),14,1))*7+VALUE(MID(TEXT(D10,"000000000000000"),13,1))*13+VALUE(MID(TEXT(D10,"000000000000000"),12,1))*17+VALUE(MID(TEXT(D10,"000000000000000"),11,1))*19+VALUE(MID(TEXT(D10,"000000000000000"),10,1))*23+VALUE(MID(TEXT(D10,"000000000000000"),9,1))*29+VALUE(MID(TEXT(D10,"000000000000000"),8,1))*37+VALUE(MID(TEXT(D10,"000000000000000"),7,1))*41+VALUE(MID(TEXT(D10,"000000000000000"),6,1))*43+VALUE(MID(TEXT(D10,"000000000000000"),5,1))*47+VALUE(MID(TEXT(D10,"000000000000000"),4,1))*53+VALUE(MID(TEXT(D10,"000000000000000"),3,1))*59+VALUE(MID(TEXT(D10,"000000000000000"),2,1))*67+VALUE(MID(TEXT(D10,"000000000000000"),1,1))*71),11))=1,1,11-(MOD((VALUE(MID(TEXT(D10,"000000000000000"),15,1))*3+VALUE(MID(TEXT(D10,"000000000000000"),14,1))*7+VALUE(MID(TEXT(D10,"000000000000000"),13,1))*13+VALUE(MID(TEXT(D10,"000000000000000"),12,1))*17+VALUE(MID(TEXT(D10,"000000000000000"),11,1))*19+VALUE(MID(TEXT(D10,"000000000000000"),10,1))*23+VALUE(MID(TEXT(D10,"000000000000000"),9,1))*29+VALUE(MID(TEXT(D10,"000000000000000"),8,1))*37+VALUE(MID(TEXT(D10,"000000000000000"),7,1))*41+VALUE(MID(TEXT(D10,"000000000000000"),6,1))*43+VALUE(MID(TEXT(D10,"000000000000000"),5,1))*47+VALUE(MID(TEXT(D10,"000000000000000"),4,1))*53+VALUE(MID(TEXT(D10,"000000000000000"),3,1))*59+VALUE(MID(TEXT(D10,"000000000000000"),2,1))*67+VALUE(MID(TEXT(D10,"000000000000000"),1,1))*71),11)))) -> 2 | F10: =+AM10 -> 1000000 | G10: =+F10*$G$5 -> 190000 | H10: NO | I10: =IF(H10="S",-F10*$I$5,"NO RETENCIÓN") -> NO RETENCIÓN | J10: =+F10+G10 -> 1190000 | K10: =SUM(F10:I10) -> 1190000 | Q10: =+AL10 -> 0 | U10: SI | V10: =ROUND(IF(U10="SI",SUMIF('Facturas año anterior'!$B$8:$B$81,B10,'Facturas año anterior'!$V$8:$V$81)*(100%+$V$5),0),-3)+ROUND(IF(U10="SI",SUMIF('C de C año anterior'!$B$8:$B$210,B10,'C de C año anterior'!$Q$8:$Q$210)*(100%+$V$5),0),-3) -> 773000 | X10: =ROUND(IF(W10="SI",V10*$X$5,0),-3) -> 0 | Z10: =ROUND(IF(Y10="SI",V10*$Z$5,0),-3) -> 0 | AB10: =ROUND(IF(AA10="SI",V10*$AB$5,0),-3) -> 0 | AD10: =ROUND(IF(AC10="SI",V10*$AD$5,0),-3) -> 0 | AF10: =ROUND(IF(AE10="SI",V10*$AF$5,0),-3) -> 0 | AH10: =ROUND(IF(AG10="SI",V10*$AH$5,0),-3) -> 0 | AI10: SI | AJ10: =IF(AI10="SI",V10*$AJ$5,0) -> 231900 | AK10: =SUMIF('Otras Asesorías y Préstamos'!$B$7:$B$242,B10,'Otras Asesorías y Préstamos'!$F$7:$F$242) -> 0 | AL10: =SUMIF('Otras Asesorías y Préstamos'!$B$7:$B$242,B10,'Otras Asesorías y Préstamos'!$V$7:$V$242) -> 0 | AM10: =ROUND(SUM(V10:AK10),-4) -> 1000000
A11: =+A10+1 -> 3 | B11: NOMBRE 3 | C11: =_xlfn.XLOOKUP(B11,Códigos!$B$8:$B$406,Códigos!$A$8:$A$406,"Verificar",0) -> 300 | D11: =_xlfn.XLOOKUP(B11,'Consolidado Cobros'!$B$10:$B$268,'Consolidado Cobros'!$C$10:$C$268,"Verificar",0) -> 70116694 | E11: =IF((MOD((VALUE(MID(TEXT(D11,"000000000000000"),15,1))*3+VALUE(MID(TEXT(D11,"000000000000000"),14,1))*7+VALUE(MID(TEXT(D11,"000000000000000"),13,1))*13+VALUE(MID(TEXT(D11,"000000000000000"),12,1))*17+VALUE(MID(TEXT(D11,"000000000000000"),11,1))*19+VALUE(MID(TEXT(D11,"000000000000000"),10,1))*23+VALUE(MID(TEXT(D11,"000000000000000"),9,1))*29+VALUE(MID(TEXT(D11,"000000000000000"),8,1))*37+VALUE(MID(TEXT(D11,"000000000000000"),7,1))*41+VALUE(MID(TEXT(D11,"000000000000000"),6,1))*43+VALUE(MID(TEXT(D11,"000000000000000"),5,1))*47+VALUE(MID(TEXT(D11,"000000000000000"),4,1))*53+VALUE(MID(TEXT(D11,"000000000000000"),3,1))*59+VALUE(MID(TEXT(D11,"000000000000000"),2,1))*67+VALUE(MID(TEXT(D11,"000000000000000"),1,1))*71),11))=0,0,IF((MOD((VALUE(MID(TEXT(D11,"000000000000000"),15,1))*3+VALUE(MID(TEXT(D11,"000000000000000"),14,1))*7+VALUE(MID(TEXT(D11,"000000000000000"),13,1))*13+VALUE(MID(TEXT(D11,"000000000000000"),12,1))*17+VALUE(MID(TEXT(D11,"000000000000000"),11,1))*19+VALUE(MID(TEXT(D11,"000000000000000"),10,1))*23+VALUE(MID(TEXT(D11,"000000000000000"),9,1))*29+VALUE(MID(TEXT(D11,"000000000000000"),8,1))*37+VALUE(MID(TEXT(D11,"000000000000000"),7,1))*41+VALUE(MID(TEXT(D11,"000000000000000"),6,1))*43+VALUE(MID(TEXT(D11,"000000000000000"),5,1))*47+VALUE(MID(TEXT(D11,"000000000000000"),4,1))*53+VALUE(MID(TEXT(D11,"000000000000000"),3,1))*59+VALUE(MID(TEXT(D11,"000000000000000"),2,1))*67+VALUE(MID(TEXT(D11,"000000000000000"),1,1))*71),11))=1,1,11-(MOD((VALUE(MID(TEXT(D11,"000000000000000"),15,1))*3+VALUE(MID(TEXT(D11,"000000000000000"),14,1))*7+VALUE(MID(TEXT(D11,"000000000000000"),13,1))*13+VALUE(MID(TEXT(D11,"000000000000000"),12,1))*17+VALUE(MID(TEXT(D11,"000000000000000"),11,1))*19+VALUE(MID(TEXT(D11,"000000000000000"),10,1))*23+VALUE(MID(TEXT(D11,"000000000000000"),9,1))*29+VALUE(MID(TEXT(D11,"000000000000000"),8,1))*37+VALUE(MID(TEXT(D11,"000000000000000"),7,1))*41+VALUE(MID(TEXT(D11,"000000000000000"),6,1))*43+VALUE(MID(TEXT(D11,"000000000000000"),5,1))*47+VALUE(MID(TEXT(D11,"000000000000000"),4,1))*53+VALUE(MID(TEXT(D11,"000000000000000"),3,1))*59+VALUE(MID(TEXT(D11,"000000000000000"),2,1))*67+VALUE(MID(TEXT(D11,"000000000000000"),1,1))*71),11)))) -> 5 | F11: =+AM11 -> 1080000 | G11: =+F11*$G$5 -> 205200 | H11: S | I11: =IF(H11="S",-F11*$I$5,"NO RETENCIÓN") -> -118800 | J11: =+F11+G11 -> 1285200 | K11: =SUM(F11:I11) -> 1166400 | Q11: =+AL11 -> 0 | U11: SI | V11: =ROUND(IF(U11="SI",SUMIF('Facturas año anterior'!$B$8:$B$81,B11,'Facturas año anterior'!$V$8:$V$81)*(100%+$V$5),0),-3)+ROUND(IF(U11="SI",SUMIF('C de C año anterior'!$B$8:$B$210,B11,'C de C año anterior'!$Q$8:$Q$210)*(100%+$V$5),0),-3) -> 1083000 | X11: =ROUND(IF(W11="SI",V11*$X$5,0),-3) -> 0 | Z11: =ROUND(IF(Y11="SI",V11*$Z$5,0),-3) -> 0 | AB11: =ROUND(IF(AA11="SI",V11*$AB$5,0),-3) -> 0 | AD11: =ROUND(IF(AC11="SI",V11*$AD$5,0),-3) -> 0 | AF11: =ROUND(IF(AE11="SI",V11*$AF$5,0),-3) -> 0 | AH11: =ROUND(IF(AG11="SI",V11*$AH$5,0),-3) -> 0 | AJ11: =IF(AI11="SI",V11*$AJ$5,0) -> 0 | AK11: =SUMIF('Otras Asesorías y Préstamos'!$B$7:$B$242,B11,'Otras Asesorías y Préstamos'!$F$7:$F$242) -> 0 | AL11: =SUMIF('Otras Asesorías y Préstamos'!$B$7:$B$242,B11,'Otras Asesorías y Préstamos'!$V$7:$V$242) -> 0 | AM11: =ROUND(SUM(V11:AK11),-4) -> 1080000
A12: =+A11+1 -> 4 | B12: NOMBRE 4 | C12: =_xlfn.XLOOKUP(B12,Códigos!$B$8:$B$406,Códigos!$A$8:$A$406,"Verificar",0) -> 312 | D12: =_xlfn.XLOOKUP(B12,'Consolidado Cobros'!$B$10:$B$268,'Consolidado Cobros'!$C$10:$C$268,"Verificar",0) -> 3349249 | E12: =IF((MOD((VALUE(MID(TEXT(D12,"000000000000000"),15,1))*3+VALUE(MID(TEXT(D12,"000000000000000"),14,1))*7+VALUE(MID(TEXT(D12,"000000000000000"),13,1))*13+VALUE(MID(TEXT(D12,"000000000000000"),12,1))*17+VALUE(MID(TEXT(D12,"000000000000000"),11,1))*19+VALUE(MID(TEXT(D12,"000000000000000"),10,1))*23+VALUE(MID(TEXT(D12,"000000000000000"),9,1))*29+VALUE(MID(TEXT(D12,"000000000000000"),8,1))*37+VALUE(MID(TEXT(D12,"000000000000000"),7,1))*41+VALUE(MID(TEXT(D12,"000000000000000"),6,1))*43+VALUE(MID(TEXT(D12,"000000000000000"),5,1))*47+VALUE(MID(TEXT(D12,"000000000000000"),4,1))*53+VALUE(MID(TEXT(D12,"000000000000000"),3,1))*59+VALUE(MID(TEXT(D12,"000000000000000"),2,1))*67+VALUE(MID(TEXT(D12,"000000000000000"),1,1))*71),11))=0,0,IF((MOD((VALUE(MID(TEXT(D12,"000000000000000"),15,1))*3+VALUE(MID(TEXT(D12,"000000000000000"),14,1))*7+VALUE(MID(TEXT(D12,"000000000000000"),13,1))*13+VALUE(MID(TEXT(D12,"000000000000000"),12,1))*17+VALUE(MID(TEXT(D12,"000000000000000"),11,1))*19+VALUE(MID(TEXT(D12,"000000000000000"),10,1))*23+VALUE(MID(TEXT(D12,"000000000000000"),9,1))*29+VALUE(MID(TEXT(D12,"000000000000000"),8,1))*37+VALUE(MID(TEXT(D12,"000000000000000"),7,1))*41+VALUE(MID(TEXT(D12,"000000000000000"),6,1))*43+VALUE(MID(TEXT(D12,"000000000000000"),5,1))*47+VALUE(MID(TEXT(D12,"000000000000000"),4,1))*53+VALUE(MID(TEXT(D12,"000000000000000"),3,1))*59+VALUE(MID(TEXT(D12,"000000000000000"),2,1))*67+VALUE(MID(TEXT(D12,"000000000000000"),1,1))*71),11))=1,1,11-(MOD((VALUE(MID(TEXT(D12,"000000000000000"),15,1))*3+VALUE(MID(TEXT(D12,"000000000000000"),14,1))*7+VALUE(MID(TEXT(D12,"000000000000000"),13,1))*13+VALUE(MID(TEXT(D12,"000000000000000"),12,1))*17+VALUE(MID(TEXT(D12,"000000000000000"),11,1))*19+VALUE(MID(TEXT(D12,"000000000000000"),10,1))*23+VALUE(MID(TEXT(D12,"000000000000000"),9,1))*29+VALUE(MID(TEXT(D12,"000000000000000"),8,1))*37+VALUE(MID(TEXT(D12,"000000000000000"),7,1))*41+VALUE(MID(TEXT(D12,"000000000000000"),6,1))*43+VALUE(MID(TEXT(D12,"000000000000000"),5,1))*47+VALUE(MID(TEXT(D12,"000000000000000"),4,1))*53+VALUE(MID(TEXT(D12,"000000000000000"),3,1))*59+VALUE(MID(TEXT(D12,"000000000000000"),2,1))*67+VALUE(MID(TEXT(D12,"000000000000000"),1,1))*71),11)))) -> 7 | F12: =+AM12 -> 2990000 | G12: =+F12*$G$5 -> 568100 | H12: S | I12: =IF(H12="S",-F12*$I$5,"NO RETENCIÓN") -> -328900 | J12: =+F12+G12 -> 3558100 | K12: =SUM(F12:I12) -> 3229200 | Q12: =+AL12 -> 0 | U12: SI | V12: =ROUND(IF(U12="SI",SUMIF('Facturas año anterior'!$B$8:$B$81,B12,'Facturas año anterior'!$V$8:$V$81)*(100%+$V$5),0),-3)+ROUND(IF(U12="SI",SUMIF('C de C año anterior'!$B$8:$B$210,B12,'C de C año anterior'!$Q$8:$Q$210)*(100%+$V$5),0),-3) -> 1328000 | W12: SI | X12: =ROUND(IF(W12="SI",V12*$X$5,0),-3) -> 664000 | Y12: SI | Z12: =ROUND(IF(Y12="SI",V12*$Z$5,0),-3) -> 996000 | AB12: =ROUND(IF(AA12="SI",V12*$AB$5,0),-3) -> 0 | AD12: =ROUND(IF(AC12="SI",V12*$AD$5,0),-3) -> 0 | AF12: =ROUND(IF(AE12="SI",V12*$AF$5,0),-3) -> 0 | AH12: =ROUND(IF(AG12="SI",V12*$AH$5,0),-3) -> 0 | AJ12: =IF(AI12="SI",V12*$AJ$5,0) -> 0 | AK12: =SUMIF('Otras Asesorías y Préstamos'!$B$7:$B$242,B12,'Otras Asesorías y Préstamos'!$F$7:$F$242) -> 0 | AL12: =SUMIF('Otras Asesorías y Préstamos'!$B$7:$B$242,B12,'Otras Asesorías y Préstamos'!$V$7:$V$242) -> 0 | AM12: =ROUND(SUM(V12:AK12),-4) -> 2990000
A13: =+A12+1 -> 5 | B13: NOMBRE 5 | C13: =_xlfn.XLOOKUP(B13,Códigos!$B$8:$B$406,Códigos!$A$8:$A$406,"Verificar",0) -> 217 | D13: =_xlfn.XLOOKUP(B13,'Consolidado Cobros'!$B$10:$B$268,'Consolidado Cobros'!$C$10:$C$268,"Verificar",0) -> 71632774 | E13: =IF((MOD((VALUE(MID(TEXT(D13,"000000000000000"),15,1))*3+VALUE(MID(TEXT(D13,"000000000000000"),14,1))*7+VALUE(MID(TEXT(D13,"000000000000000"),13,1))*13+VALUE(MID(TEXT(D13,"000000000000000"),12,1))*17+VALUE(MID(TEXT(D13,"000000000000000"),11,1))*19+VALUE(MID(TEXT(D13,"000000000000000"),10,1))*23+VALUE(MID(TEXT(D13,"000000000000000"),9,1))*29+VALUE(MID(TEXT(D13,"000000000000000"),8,1))*37+VALUE(MID(TEXT(D13,"000000000000000"),7,1))*41+VALUE(MID(TEXT(D13,"000000000000000"),6,1))*43+VALUE(MID(TEXT(D13,"000000000000000"),5,1))*47+VALUE(MID(TEXT(D13,"000000000000000"),4,1))*53+VALUE(MID(TEXT(D13,"000000000000000"),3,1))*59+VALUE(MID(TEXT(D13,"000000000000000"),2,1))*67+VALUE(MID(TEXT(D13,"000000000000000"),1,1))*71),11))=0,0,IF((MOD((VALUE(MID(TEXT(D13,"000000000000000"),15,1))*3+VALUE(MID(TEXT(D13,"000000000000000"),14,1))*7+VALUE(MID(TEXT(D13,"000000000000000"),13,1))*13+VALUE(MID(TEXT(D13,"000000000000000"),12,1))*17+VALUE(MID(TEXT(D13,"000000000000000"),11,1))*19+VALUE(MID(TEXT(D13,"000000000000000"),10,1))*23+VALUE(MID(TEXT(D13,"000000000000000"),9,1))*29+VALUE(MID(TEXT(D13,"000000000000000"),8,1))*37+VALUE(MID(TEXT(D13,"000000000000000"),7,1))*41+VALUE(MID(TEXT(D13,"000000000000000"),6,1))*43+VALUE(MID(TEXT(D13,"000000000000000"),5,1))*47+VALUE(MID(TEXT(D13,"000000000000000"),4,1))*53+VALUE(MID(TEXT(D13,"000000000000000"),3,1))*59+VALUE(MID(TEXT(D13,"000000000000000"),2,1))*67+VALUE(MID(TEXT(D13,"000000000000000"),1,1))*71),11))=1,1,11-(MOD((VALUE(MID(TEXT(D13,"000000000000000"),15,1))*3+VALUE(MID(TEXT(D13,"000000000000000"),14,1))*7+VALUE(MID(TEXT(D13,"000000000000000"),13,1))*13+VALUE(MID(TEXT(D13,"000000000000000"),12,1))*17+VALUE(MID(TEXT(D13,"000000000000000"),11,1))*19+VALUE(MID(TEXT(D13,"000000000000000"),10,1))*23+VALUE(MID(TEXT(D13,"000000000000000"),9,1))*29+VALUE(MID(TEXT(D13,"000000000000000"),8,1))*37+VALUE(MID(TEXT(D13,"000000000000000"),7,1))*41+VALUE(MID(TEXT(D13,"000000000000000"),6,1))*43+VALUE(MID(TEXT(D13,"000000000000000"),5,1))*47+VALUE(MID(TEXT(D13,"000000000000000"),4,1))*53+VALUE(MID(TEXT(D13,"000000000000000"),3,1))*59+VALUE(MID(TEXT(D13,"000000000000000"),2,1))*67+VALUE(MID(TEXT(D13,"000000000000000"),1,1))*71),11)))) -> 2 | F13: =+AM13 -> 2430000 | G13: =+F13*$G$5 -> 461700 | H13: S | I13: =IF(H13="S",-F13*$I$5,"NO RETENCIÓN") -> -267300 | J13: =+F13+G13 -> 2891700 | K13: =SUM(F13:I13) -> 2624400 | Q13: =+AL13 -> 0 | U13: SI | V13: =ROUND(IF(U13="SI",SUMIF('Facturas año anterior'!$B$8:$B$81,B13,'Facturas año anterior'!$V$8:$V$81)*(100%+$V$5),0),-3)+ROUND(IF(U13="SI",SUMIF('C de C año anterior'!$B$8:$B$210,B13,'C de C año anterior'!$Q$8:$Q$210)*(100%+$V$5),0),-3) -> 2332000 | X13: =ROUND(IF(W13="SI",V13*$X$5,0),-3) -> 0 | Z13: =ROUND(IF(Y13="SI",V13*$Z$5,0),-3) -> 0 | AB13: =ROUND(IF(AA13="SI",V13*$AB$5,0),-3) -> 0 | AD13: =ROUND(IF(AC13="SI",V13*$AD$5,0),-3) -> 0 | AF13: =ROUND(IF(AE13="SI",V13*$AF$5,0),-3) -> 0 | AH13: =ROUND(IF(AG13="SI",V13*$AH$5,0),-3) -> 0 | AJ13: =IF(AI13="SI",V13*$AJ$5,0) -> 0 | AK13: =SUMIF('Otras Asesorías y Préstamos'!$B$7:$B$242,B13,'Otras Asesorías y Préstamos'!$F$7:$F$242) -> 100000 | AL13: =SUMIF('Otras Asesorías y Préstamos'!$B$7:$B$242,B13,'Otras Asesorías y Préstamos'!$V$7:$V$242) -> 0 | AM13: =ROUND(SUM(V13:AK13),-4) -> 2430000
A14: =+A13+1 -> 6 | B14: NOMBRE 6 | C14: =_xlfn.XLOOKUP(B14,Códigos!$B$8:$B$406,Códigos!$A$8:$A$406,"Verificar",0) -> 42 | D14: =_xlfn.XLOOKUP(B14,'Consolidado Cobros'!$B$10:$B$268,'Consolidado Cobros'!$C$10:$C$268,"Verificar",0) -> 21315528 | E14: =IF((MOD((VALUE(MID(TEXT(D14,"000000000000000"),15,1))*3+VALUE(MID(TEXT(D14,"000000000000000"),14,1))*7+VALUE(MID(TEXT(D14,"000000000000000"),13,1))*13+VALUE(MID(TEXT(D14,"000000000000000"),12,1))*17+VALUE(MID(TEXT(D14,"000000000000000"),11,1))*19+VALUE(MID(TEXT(D14,"000000000000000"),10,1))*23+VALUE(MID(TEXT(D14,"000000000000000"),9,1))*29+VALUE(MID(TEXT(D14,"000000000000000"),8,1))*37+VALUE(MID(TEXT(D14,"000000000000000"),7,1))*41+VALUE(MID(TEXT(D14,"000000000000000"),6,1))*43+VALUE(MID(TEXT(D14,"000000000000000"),5,1))*47+VALUE(MID(TEXT(D14,"000000000000000"),4,1))*53+VALUE(MID(TEXT(D14,"000000000000000"),3,1))*59+VALUE(MID(TEXT(D14,"000000000000000"),2,1))*67+VALUE(MID(TEXT(D14,"000000000000000"),1,1))*71),11))=0,0,IF((MOD((VALUE(MID(TEXT(D14,"000000000000000"),15,1))*3+VALUE(MID(TEXT(D14,"000000000000000"),14,1))*7+VALUE(MID(TEXT(D14,"000000000000000"),13,1))*13+VALUE(MID(TEXT(D14,"000000000000000"),12,1))*17+VALUE(MID(TEXT(D14,"000000000000000"),11,1))*19+VALUE(MID(TEXT(D14,"000000000000000"),10,1))*23+VALUE(MID(TEXT(D14,"000000000000000"),9,1))*29+VALUE(MID(TEXT(D14,"000000000000000"),8,1))*37+VALUE(MID(TEXT(D14,"000000000000000"),7,1))*41+VALUE(MID(TEXT(D14,"000000000000000"),6,1))*43+VALUE(MID(TEXT(D14,"000000000000000"),5,1))*47+VALUE(MID(TEXT(D14,"000000000000000"),4,1))*53+VALUE(MID(TEXT(D14,"000000000000000"),3,1))*59+VALUE(MID(TEXT(D14,"000000000000000"),2,1))*67+VALUE(MID(TEXT(D14,"000000000000000"),1,1))*71),11))=1,1,11-(MOD((VALUE(MID(TEXT(D14,"000000000000000"),15,1))*3+VALUE(MID(TEXT(D14,"000000000000000"),14,1))*7+VALUE(MID(TEXT(D14,"000000000000000"),13,1))*13+VALUE(MID(TEXT(D14,"000000000000000"),12,1))*17+VALUE(MID(TEXT(D14,"000000000000000"),11,1))*19+VALUE(MID(TEXT(D14,"000000000000000"),10,1))*23+VALUE(MID(TEXT(D14,"000000000000000"),9,1))*29+VALUE(MID(TEXT(D14,"000000000000000"),8,1))*37+VALUE(MID(TEXT(D14,"000000000000000"),7,1))*41+VALUE(MID(TEXT(D14,"000000000000000"),6,1))*43+VALUE(MID(TEXT(D14,"000000000000000"),5,1))*47+VALUE(MID(TEXT(D14,"000000000000000"),4,1))*53+VALUE(MID(TEXT(D14,"000000000000000"),3,1))*59+VALUE(MID(TEXT(D14,"000000000000000"),2,1))*67+VALUE(MID(TEXT(D14,"000000000000000"),1,1))*71),11)))) -> 6 | F14: =+AM14 -> 1830000 | G14: =+F14*$G$5 -> 347700 | H14: S | I14: =IF(H14="S",-F14*$I$5,"NO RETENCIÓN") -> -201300 | J14: =+F14+G14 -> 2177700 | K14: =SUM(F14:I14) -> 1976400 | Q14: =+AL14 -> 0 | S14: Fra con -San Antonio de la Almería | U14: SI | V14: =ROUND(IF(U14="SI",SUMIF('Facturas año anterior'!$B$8:$B$81,B14,'Facturas año anterior'!$V$8:$V$81)*(100%+$V$5),0),-3)+ROUND(IF(U14="SI",SUMIF('C de C año anterior'!$B$8:$B$210,B14,'C de C año anterior'!$Q$8:$Q$210)*(100%+$V$5),0),-3) -> 1830000 | X14: =ROUND(IF(W14="SI",V14*$X$5,0),-3) -> 0 | Z14: =ROUND(IF(Y14="SI",V14*$Z$5,0),-3) -> 0 | AB14: =ROUND(IF(AA14="SI",V14*$AB$5,0),-3) -> 0 | AD14: =ROUND(IF(AC14="SI",V14*$AD$5,0),-3) -> 0 | AF14: =ROUND(IF(AE14="SI",V14*$AF$5,0),-3) -> 0 | AH14: =ROUND(IF(AG14="SI",V14*$AH$5,0),-3) -> 0 | AJ14: =IF(AI14="SI",V14*$AJ$5,0) -> 0 | AK14: =SUMIF('Otras Asesorías y Préstamos'!$B$7:$B$242,B14,'Otras Asesorías y Préstamos'!$F$7:$F$242) -> 0 | AL14: =SUMIF('Otras Asesorías y Préstamos'!$B$7:$B$242,B14,'Otras Asesorías y Préstamos'!$V$7:$V$242) -> 0 | AM14: =ROUND(SUM(V14:AK14),-4) -> 1830000
A15: =+A14+1 -> 7 | B15: NOMBRE 7 | C15: =_xlfn.XLOOKUP(B15,Códigos!$B$8:$B$406,Códigos!$A$8:$A$406,"Verificar",0) -> 43 | D15: =_xlfn.XLOOKUP(B15,'Consolidado Cobros'!$B$10:$B$268,'Consolidado Cobros'!$C$10:$C$268,"Verificar",0) -> 32336950 | E15: =IF((MOD((VALUE(MID(TEXT(D15,"000000000000000"),15,1))*3+VALUE(MID(TEXT(D15,"000000000000000"),14,1))*7+VALUE(MID(TEXT(D15,"000000000000000"),13,1))*13+VALUE(MID(TEXT(D15,"000000000000000"),12,1))*17+VALUE(MID(TEXT(D15,"000000000000000"),11,1))*19+VALUE(MID(TEXT(D15,"000000000000000"),10,1))*23+VALUE(MID(TEXT(D15,"000000000000000"),9,1))*29+VALUE(MID(TEXT(D15,"000000000000000"),8,1))*37+VALUE(MID(TEXT(D15,"000000000000000"),7,1))*41+VALUE(MID(TEXT(D15,"000000000000000"),6,1))*43+VALUE(MID(TEXT(D15,"000000000000000"),5,1))*47+VALUE(MID(TEXT(D15,"000000000000000"),4,1))*53+VALUE(MID(TEXT(D15,"000000000000000"),3,1))*59+VALUE(MID(TEXT(D15,"000000000000000"),2,1))*67+VALUE(MID(TEXT(D15,"000000000000000"),1,1))*71),11))=0,0,IF((MOD((VALUE(MID(TEXT(D15,"000000000000000"),15,1))*3+VALUE(MID(TEXT(D15,"000000000000000"),14,1))*7+VALUE(MID(TEXT(D15,"000000000000000"),13,1))*13+VALUE(MID(TEXT(D15,"000000000000000"),12,1))*17+VALUE(MID(TEXT(D15,"000000000000000"),11,1))*19+VALUE(MID(TEXT(D15,"000000000000000"),10,1))*23+VALUE(MID(TEXT(D15,"000000000000000"),9,1))*29+VALUE(MID(TEXT(D15,"000000000000000"),8,1))*37+VALUE(MID(TEXT(D15,"000000000000000"),7,1))*41+VALUE(MID(TEXT(D15,"000000000000000"),6,1))*43+VALUE(MID(TEXT(D15,"000000000000000"),5,1))*47+VALUE(MID(TEXT(D15,"000000000000000"),4,1))*53+VALUE(MID(TEXT(D15,"000000000000000"),3,1))*59+VALUE(MID(TEXT(D15,"000000000000000"),2,1))*67+VALUE(MID(TEXT(D15,"000000000000000"),1,1))*71),11))=1,1,11-(MOD((VALUE(MID(TEXT(D15,"000000000000000"),15,1))*3+VALUE(MID(TEXT(D15,"000000000000000"),14,1))*7+VALUE(MID(TEXT(D15,"000000000000000"),13,1))*13+VALUE(MID(TEXT(D15,"000000000000000"),12,1))*17+VALUE(MID(TEXT(D15,"000000000000000"),11,1))*19+VALUE(MID(TEXT(D15,"000000000000000"),10,1))*23+VALUE(MID(TEXT(D15,"000000000000000"),9,1))*29+VALUE(MID(TEXT(D15,"000000000000000"),8,1))*37+VALUE(MID(TEXT(D15,"000000000000000"),7,1))*41+VALUE(MID(TEXT(D15,"000000000000000"),6,1))*43+VALUE(MID(TEXT(D15,"000000000000000"),5,1))*47+VALUE(MID(TEXT(D15,"000000000000000"),4,1))*53+VALUE(MID(TEXT(D15,"000000000000000"),3,1))*59+VALUE(MID(TEXT(D15,"000000000000000"),2,1))*67+VALUE(MID(TEXT(D15,"000000000000000"),1,1))*71),11)))) -> 1 | F15: =+AM15 -> 2390000 | G15: =+F15*$G$5 -> 454100 | H15: S | I15: =IF(H15="S",-F15*$I$5,"NO RETENCIÓN") -> -262900 | J15: =+F15+G15 -> 2844100 | K15: =SUM(F15:I15) -> 2581200 | Q15: =+AL15 -> 0 | S15: Fra con -San Antonio de la Almería | U15: SI | V15: =ROUND(IF(U15="SI",SUMIF('Facturas año anterior'!$B$8:$B$81,B15,'Facturas año anterior'!$V$8:$V$81)*(100%+$V$5),0),-3)+ROUND(IF(U15="SI",SUMIF('C de C año anterior'!$B$8:$B$210,B15,'C de C año anterior'!$Q$8:$Q$210)*(100%+$V$5),0),-3) -> 2010000 | X15: =ROUND(IF(W15="SI",V15*$X$5,0),-3) -> 0 | Z15: =ROUND(IF(Y15="SI",V15*$Z$5,0),-3) -> 0 | AB15: =ROUND(IF(AA15="SI",V15*$AB$5,0),-3) -> 0 | AD15: =ROUND(IF(AC15="SI",V15*$AD$5,0),-3) -> 0 | AF15: =ROUND(IF(AE15="SI",V15*$AF$5,0),-3) -> 0 | AH15: =ROUND(IF(AG15="SI",V15*$AH$5,0),-3) -> 0 | AJ15: =IF(AI15="SI",V15*$AJ$5,0) -> 0 | AK15: =SUMIF('Otras Asesorías y Préstamos'!$B$7:$B$242,B15,'Otras Asesorías y Préstamos'!$F$7:$F$242) -> 384948.68 | AL15: =SUMIF('Otras Asesorías y Préstamos'!$B$7:$B$242,B15,'Otras Asesorías y Préstamos'!$V$7:$V$242) -> 0 | AM15: =ROUND(SUM(V15:AK15),-4) -> 2390000
A16: =+A15+1 -> 8 | B16: NOMBRE 8 | C16: =_xlfn.XLOOKUP(B16,Códigos!$B$8:$B$406,Códigos!$A$8:$A$406,"Verificar",0) -> 44 | D16: =_xlfn.XLOOKUP(B16,'Consolidado Cobros'!$B$10:$B$268,'Consolidado Cobros'!$C$10:$C$268,"Verificar",0) -> 1152450831 | E16: =IF((MOD((VALUE(MID(TEXT(D16,"000000000000000"),15,1))*3+VALUE(MID(TEXT(D16,"000000000000000"),14,1))*7+VALUE(MID(TEXT(D16,"000000000000000"),13,1))*13+VALUE(MID(TEXT(D16,"000000000000000"),12,1))*17+VALUE(MID(TEXT(D16,"000000000000000"),11,1))*19+VALUE(MID(TEXT(D16,"000000000000000"),10,1))*23+VALUE(MID(TEXT(D16,"000000000000000"),9,1))*29+VALUE(MID(TEXT(D16,"000000000000000"),8,1))*37+VALUE(MID(TEXT(D16,"000000000000000"),7,1))*41+VALUE(MID(TEXT(D16,"000000000000000"),6,1))*43+VALUE(MID(TEXT(D16,"000000000000000"),5,1))*47+VALUE(MID(TEXT(D16,"000000000000000"),4,1))*53+VALUE(MID(TEXT(D16,"000000000000000"),3,1))*59+VALUE(MID(TEXT(D16,"000000000000000"),2,1))*67+VALUE(MID(TEXT(D16,"000000000000000"),1,1))*71),11))=0,0,IF((MOD((VALUE(MID(TEXT(D16,"000000000000000"),15,1))*3+VALUE(MID(TEXT(D16,"000000000000000"),14,1))*7+VALUE(MID(TEXT(D16,"000000000000000"),13,1))*13+VALUE(MID(TEXT(D16,"000000000000000"),12,1))*17+VALUE(MID(TEXT(D16,"000000000000000"),11,1))*19+VALUE(MID(TEXT(D16,"000000000000000"),10,1))*23+VALUE(MID(TEXT(D16,"000000000000000"),9,1))*29+VALUE(MID(TEXT(D16,"000000000000000"),8,1))*37+VALUE(MID(TEXT(D16,"000000000000000"),7,1))*41+VALUE(MID(TEXT(D16,"000000000000000"),6,1))*43+VALUE(MID(TEXT(D16,"000000000000000"),5,1))*47+VALUE(MID(TEXT(D16,"000000000000000"),4,1))*53+VALUE(MID(TEXT(D16,"000000000000000"),3,1))*59+VALUE(MID(TEXT(D16,"000000000000000"),2,1))*67+VALUE(MID(TEXT(D16,"000000000000000"),1,1))*71),11))=1,1,11-(MOD((VALUE(MID(TEXT(D16,"000000000000000"),15,1))*3+VALUE(MID(TEXT(D16,"000000000000000"),14,1))*7+VALUE(MID(TEXT(D16,"000000000000000"),13,1))*13+VALUE(MID(TEXT(D16,"000000000000000"),12,1))*17+VALUE(MID(TEXT(D16,"000000000000000"),11,1))*19+VALUE(MID(TEXT(D16,"000000000000000"),10,1))*23+VALUE(MID(TEXT(D16,"000000000000000"),9,1))*29+VALUE(MID(TEXT(D16,"000000000000000"),8,1))*37+VALUE(MID(TEXT(D16,"000000000000000"),7,1))*41+VALUE(MID(TEXT(D16,"000000000000000"),6,1))*43+VALUE(MID(TEXT(D16,"000000000000000"),5,1))*47+VALUE(MID(TEXT(D16,"000000000000000"),4,1))*53+VALUE(MID(TEXT(D16,"000000000000000"),3,1))*59+VALUE(MID(TEXT(D16,"000000000000000"),2,1))*67+VALUE(MID(TEXT(D16,"000000000000000"),1,1))*71),11)))) -> 7 | F16: =+AM16 -> 220000 | G16: =+F16*$G$5 -> 41800 | H16: S | I16: =IF(H16="S",-F16*$I$5,"NO RETENCIÓN") -> -24200 | J16: =+F16+G16 -> 261800 | K16: =SUM(F16:I16) -> 237600 | Q16: =+AL16 -> 0 | S16: Fra con -Ruiz González Álvaro H. | U16: SI | V16: =ROUND(IF(U16="SI",SUMIF('Facturas año anterior'!$B$8:$B$81,B16,'Facturas año anterior'!$V$8:$V$81)*(100%+$V$5),0),-3)+ROUND(IF(U16="SI",SUMIF('C de C año anterior'!$B$8:$B$210,B16,'C de C año anterior'!$Q$8:$Q$210)*(100%+$V$5),0),-3) -> 221000 | X16: =ROUND(IF(W16="SI",V16*$X$5,0),-3) -> 0 | Z16: =ROUND(IF(Y16="SI",V16*$Z$5,0),-3) -> 0 | AB16: =ROUND(IF(AA16="SI",V16*$AB$5,0),-3) -> 0 | AD16: =ROUND(IF(AC16="SI",V16*$AD$5,0),-3) -> 0 | AF16: =ROUND(IF(AE16="SI",V16*$AF$5,0),-3) -> 0 | AH16: =ROUND(IF(AG16="SI",V16*$AH$5,0),-3) -> 0 | AJ16: =IF(AI16="SI",V16*$AJ$5,0) -> 0 | AK16: =SUMIF('Otras Asesorías y Préstamos'!$B$7:$B$242,B16,'Otras Asesorías y Préstamos'!$F$7:$F$242) -> 0 | AL16: =SUMIF('Otras Asesorías y Préstamos'!$B$7:$B$242,B16,'Otras Asesorías y Préstamos'!$V$7:$V$242) -> 0 | AM16: =ROUND(SUM(V16:AK16),-4) -> 220000
A17: =+A16+1 -> 9 | U17: SI | V17: =ROUND(IF(U17="SI",SUMIF('Facturas año anterior'!$B$8:$B$81,B17,'Facturas año anterior'!$V$8:$V$81)*(100%+$V$5),0),-3)+ROUND(IF(U17="SI",SUMIF('C de C año anterior'!$B$8:$B$210,B17,'C de C año anterior'!$Q$8:$Q$210)*(100%+$V$5),0),-3) -> 0 | X17: =ROUND(IF(W17="SI",V17*$X$5,0),-3) -> 0 | Z17: =ROUND(IF(Y17="SI",V17*$Z$5,0),-3) -> 0 | AB17: =ROUND(IF(AA17="SI",V17*$AB$5,0),-3) -> 0 | AD17: =ROUND(IF(AC17="SI",V17*$AD$5,0),-3) -> 0 | AF17: =ROUND(IF(AE17="SI",V17*$AF$5,0),-3) -> 0 | AH17: =ROUND(IF(AG17="SI",V17*$AH$5,0),-3) -> 0 | AJ17: =IF(AI17="SI",V17*$AJ$5,0) -> 0 | AK17: =SUMIF('Otras Asesorías y Préstamos'!$B$7:$B$242,B17,'Otras Asesorías y Préstamos'!$F$7:$F$242) -> 0 | AL17: =SUMIF('Otras Asesorías y Préstamos'!$B$7:$B$242,B17,'Otras Asesorías y Préstamos'!$V$7:$V$242) -> 0 | AM17: =ROUND(SUM(V17:AK17),-4) -> 0
A18: =+A17+1 -> 10 | Q18: =+AL18 -> 0 | U18: SI | V18: =ROUND(IF(U18="SI",SUMIF('Facturas año anterior'!$B$8:$B$81,B18,'Facturas año anterior'!$V$8:$V$81)*(100%+$V$5),0),-3)+ROUND(IF(U18="SI",SUMIF('C de C año anterior'!$B$8:$B$210,B18,'C de C año anterior'!$Q$8:$Q$210)*(100%+$V$5),0),-3) -> 0 | X18: =ROUND(IF(W18="SI",V18*$X$5,0),-3) -> 0 | Z18: =ROUND(IF(Y18="SI",V18*$Z$5,0),-3) -> 0 | AB18: =ROUND(IF(AA18="SI",V18*$AB$5,0),-3) -> 0 | AD18: =ROUND(IF(AC18="SI",V18*$AD$5,0),-3) -> 0 | AF18: =ROUND(IF(AE18="SI",V18*$AF$5,0),-3) -> 0 | AH18: =ROUND(IF(AG18="SI",V18*$AH$5,0),-3) -> 0 | AI18: SI | AJ18: =IF(AI18="SI",V18*$AJ$5,0) -> 0 | AK18: =SUMIF('Otras Asesorías y Préstamos'!$B$7:$B$242,B18,'Otras Asesorías y Préstamos'!$F$7:$F$242) -> 0 | AL18: =SUMIF('Otras Asesorías y Préstamos'!$B$7:$B$242,B18,'Otras Asesorías y Préstamos'!$V$7:$V$242) -> 0 | AM18: =ROUND(SUM(V18:AK18),-4) -> 0
A19: =+A18+1 -> 11 | Q19: =+AL19 -> 0 | U19: SI | V19: =ROUND(IF(U19="SI",SUMIF('Facturas año anterior'!$B$8:$B$81,B19,'Facturas año anterior'!$V$8:$V$81)*(100%+$V$5),0),-3)+ROUND(IF(U19="SI",SUMIF('C de C año anterior'!$B$8:$B$210,B19,'C de C año anterior'!$Q$8:$Q$210)*(100%+$V$5),0),-3) -> 0 | X19: =ROUND(IF(W19="SI",V19*$X$5,0),-3) -> 0 | Z19: =ROUND(IF(Y19="SI",V19*$Z$5,0),-3) -> 0 | AB19: =ROUND(IF(AA19="SI",V19*$AB$5,0),-3) -> 0 | AD19: =ROUND(IF(AC19="SI",V19*$AD$5,0),-3) -> 0 | AF19: =ROUND(IF(AE19="SI",V19*$AF$5,0),-3) -> 0 | AH19: =ROUND(IF(AG19="SI",V19*$AH$5,0),-3) -> 0 | AJ19: =IF(AI19="SI",V19*$AJ$5,0) -> 0 | AK19: =SUMIF('Otras Asesorías y Préstamos'!$B$7:$B$242,B19,'Otras Asesorías y Préstamos'!$F$7:$F$242) -> 0 | AL19: =SUMIF('Otras Asesorías y Préstamos'!$B$7:$B$242,B19,'Otras Asesorías y Préstamos'!$V$7:$V$242) -> 0 | AM19: =ROUND(SUM(V19:AK19),-4) -> 0
A20: =+A19+1 -> 12 | Q20: =+AL20 -> 0 | U20: SI | V20: =ROUND(IF(U20="SI",SUMIF('Facturas año anterior'!$B$8:$B$81,B20,'Facturas año anterior'!$V$8:$V$81)*(100%+$V$5),0),-3)+ROUND(IF(U20="SI",SUMIF('C de C año anterior'!$B$8:$B$210,B20,'C de C año anterior'!$Q$8:$Q$210)*(100%+$V$5),0),-3) -> 0 | X20: =ROUND(IF(W20="SI",V20*$X$5,0),-3) -> 0 | Z20: =ROUND(IF(Y20="SI",V20*$Z$5,0),-3) -> 0 | AB20: =ROUND(IF(AA20="SI",V20*$AB$5,0),-3) -> 0 | AD20: =ROUND(IF(AC20="SI",V20*$AD$5,0),-3) -> 0 | AF20: =ROUND(IF(AE20="SI",V20*$AF$5,0),-3) -> 0 | AH20: =ROUND(IF(AG20="SI",V20*$AH$5,0),-3) -> 0 | AJ20: =IF(AI20="SI",V20*$AJ$5,0) -> 0 | AK20: =SUMIF('Otras Asesorías y Préstamos'!$B$7:$B$242,B20,'Otras Asesorías y Préstamos'!$F$7:$F$242) -> 0 | AL20: =SUMIF('Otras Asesorías y Préstamos'!$B$7:$B$242,B20,'Otras Asesorías y Préstamos'!$V$7:$V$242) -> 0 | AM20: =ROUND(SUM(V20:AK20),-4) -> 0
A21: =+A20+1 -> 13 | Q21: =+AL21 -> 0 | U21: SI | V21: =ROUND(IF(U21="SI",SUMIF('Facturas año anterior'!$B$8:$B$81,B21,'Facturas año anterior'!$V$8:$V$81)*(100%+$V$5),0),-3)+ROUND(IF(U21="SI",SUMIF('C de C año anterior'!$B$8:$B$210,B21,'C de C año anterior'!$Q$8:$Q$210)*(100%+$V$5),0),-3) -> 0 | X21: =ROUND(IF(W21="SI",V21*$X$5,0),-3) -> 0 | Z21: =ROUND(IF(Y21="SI",V21*$Z$5,0),-3) -> 0 | AB21: =ROUND(IF(AA21="SI",V21*$AB$5,0),-3) -> 0 | AD21: =ROUND(IF(AC21="SI",V21*$AD$5,0),-3) -> 0 | AF21: =ROUND(IF(AE21="SI",V21*$AF$5,0),-3) -> 0 | AH21: =ROUND(IF(AG21="SI",V21*$AH$5,0),-3) -> 0 | AI21: SI | AJ21: =IF(AI21="SI",V21*$AJ$5,0) -> 0 | AK21: =SUMIF('Otras Asesorías y Préstamos'!$B$7:$B$242,B21,'Otras Asesorías y Préstamos'!$F$7:$F$242) -> 0 | AL21: =SUMIF('Otras Asesorías y Préstamos'!$B$7:$B$242,B21,'Otras Asesorías y Préstamos'!$V$7:$V$242) -> 0 | AM21: =ROUND(SUM(V21:AK21),-4) -> 0
A22: =+A21+1 -> 14 | Q22: =+AL22 -> 0 | U22: SI | V22: =ROUND(IF(U22="SI",SUMIF('Facturas año anterior'!$B$8:$B$81,B22,'Facturas año anterior'!$V$8:$V$81)*(100%+$V$5),0),-3)+ROUND(IF(U22="SI",SUMIF('C de C año anterior'!$B$8:$B$210,B22,'C de C año anterior'!$Q$8:$Q$210)*(100%+$V$5),0),-3) -> 0 | X22: =ROUND(IF(W22="SI",V22*$X$5,0),-3) -> 0 | Z22: =ROUND(IF(Y22="SI",V22*$Z$5,0),-3) -> 0 | AB22: =ROUND(IF(AA22="SI",V22*$AB$5,0),-3) -> 0 | AD22: =ROUND(IF(AC22="SI",V22*$AD$5,0),-3) -> 0 | AF22: =ROUND(IF(AE22="SI",V22*$AF$5,0),-3) -> 0 | AH22: =ROUND(IF(AG22="SI",V22*$AH$5,0),-3) -> 0 | AI22: SI | AJ22: =IF(AI22="SI",V22*$AJ$5,0) -> 0 | AK22: =SUMIF('Otras Asesorías y Préstamos'!$B$7:$B$242,B22,'Otras Asesorías y Préstamos'!$F$7:$F$242) -> 0 | AL22: =SUMIF('Otras Asesorías y Préstamos'!$B$7:$B$242,B22,'Otras Asesorías y Préstamos'!$V$7:$V$242) -> 0 | AM22: =ROUND(SUM(V22:AK22),-4) -> 0
A23: =+A22+1 -> 15 | Q23: =+AL23 -> 0 | U23: SI | V23: =ROUND(IF(U23="SI",SUMIF('Facturas año anterior'!$B$8:$B$81,B23,'Facturas año anterior'!$V$8:$V$81)*(100%+$V$5),0),-3)+ROUND(IF(U23="SI",SUMIF('C de C año anterior'!$B$8:$B$210,B23,'C de C año anterior'!$Q$8:$Q$210)*(100%+$V$5),0),-3) -> 0 | X23: =ROUND(IF(W23="SI",V23*$X$5,0),-3) -> 0 | Z23: =ROUND(IF(Y23="SI",V23*$Z$5,0),-3) -> 0 | AB23: =ROUND(IF(AA23="SI",V23*$AB$5,0),-3) -> 0 | AD23: =ROUND(IF(AC23="SI",V23*$AD$5,0),-3) -> 0 | AF23: =ROUND(IF(AE23="SI",V23*$AF$5,0),-3) -> 0 | AH23: =ROUND(IF(AG23="SI",V23*$AH$5,0),-3) -> 0 | AI23: SI | AJ23: =IF(AI23="SI",V23*$AJ$5,0) -> 0 | AK23: =SUMIF('Otras Asesorías y Préstamos'!$B$7:$B$242,B23,'Otras Asesorías y Préstamos'!$F$7:$F$242) -> 0 | AL23: =SUMIF('Otras Asesorías y Préstamos'!$B$7:$B$242,B23,'Otras Asesorías y Préstamos'!$V$7:$V$242) -> 0 | AM23: =ROUND(SUM(V23:AK23),-4) -> 0
A24: =+A23+1 -> 16 | Q24: =+AL24 -> 0 | U24: SI | V24: =ROUND(IF(U24="SI",SUMIF('Facturas año anterior'!$B$8:$B$81,B24,'Facturas año anterior'!$V$8:$V$81)*(100%+$V$5),0),-3)+ROUND(IF(U24="SI",SUMIF('C de C año anterior'!$B$8:$B$210,B24,'C de C año anterior'!$Q$8:$Q$210)*(100%+$V$5),0),-3) -> 0 | X24: =ROUND(IF(W24="SI",V24*$X$5,0),-3) -> 0 | Z24: =ROUND(IF(Y24="SI",V24*$Z$5,0),-3) -> 0 | AB24: =ROUND(IF(AA24="SI",V24*$AB$5,0),-3) -> 0 | AD24: =ROUND(IF(AC24="SI",V24*$AD$5,0),-3) -> 0 | AF24: =ROUND(IF(AE24="SI",V24*$AF$5,0),-3) -> 0 | AH24: =ROUND(IF(AG24="SI",V24*$AH$5,0),-3) -> 0 | AJ24: =IF(AI24="SI",V24*$AJ$5,0) -> 0 | AK24: =SUMIF('Otras Asesorías y Préstamos'!$B$7:$B$242,B24,'Otras Asesorías y Préstamos'!$F$7:$F$242) -> 0 | AL24: =SUMIF('Otras Asesorías y Préstamos'!$B$7:$B$242,B24,'Otras Asesorías y Préstamos'!$V$7:$V$242) -> 0 | AM24: =ROUND(SUM(V24:AK24),-4) -> 0
A25: =+A24+1 -> 17 | Q25: =+AL25 -> 0 | U25: SI | V25: =ROUND(IF(U25="SI",SUMIF('Facturas año anterior'!$B$8:$B$81,B25,'Facturas año anterior'!$V$8:$V$81)*(100%+$V$5),0),-3)+ROUND(IF(U25="SI",SUMIF('C de C año anterior'!$B$8:$B$210,B25,'C de C año anterior'!$Q$8:$Q$210)*(100%+$V$5),0),-3) -> 0 | X25: =ROUND(IF(W25="SI",V25*$X$5,0),-3) -> 0 | Z25: =ROUND(IF(Y25="SI",V25*$Z$5,0),-3) -> 0 | AB25: =ROUND(IF(AA25="SI",V25*$AB$5,0),-3) -> 0 | AD25: =ROUND(IF(AC25="SI",V25*$AD$5,0),-3) -> 0 | AF25: =ROUND(IF(AE25="SI",V25*$AF$5,0),-3) -> 0 | AH25: =ROUND(IF(AG25="SI",V25*$AH$5,0),-3) -> 0 | AI25: SI | AJ25: =IF(AI25="SI",V25*$AJ$5,0) -> 0 | AK25: =SUMIF('Otras Asesorías y Préstamos'!$B$7:$B$242,B25,'Otras Asesorías y Préstamos'!$F$7:$F$242) -> 0 | AL25: =SUMIF('Otras Asesorías y Préstamos'!$B$7:$B$242,B25,'Otras Asesorías y Préstamos'!$V$7:$V$242) -> 0 | AM25: =ROUND(SUM(V25:AK25),-4) -> 0
A26: =+A25+1 -> 18 | Q26: =+AL26 -> 0 | U26: SI | V26: =ROUND(IF(U26="SI",SUMIF('Facturas año anterior'!$B$8:$B$81,B26,'Facturas año anterior'!$V$8:$V$81)*(100%+$V$5),0),-3)+ROUND(IF(U26="SI",SUMIF('C de C año anterior'!$B$8:$B$210,B26,'C de C año anterior'!$Q$8:$Q$210)*(100%+$V$5),0),-3) -> 0 | X26: =ROUND(IF(W26="SI",V26*$X$5,0),-3) -> 0 | Z26: =ROUND(IF(Y26="SI",V26*$Z$5,0),-3) -> 0 | AB26: =ROUND(IF(AA26="SI",V26*$AB$5,0),-3) -> 0 | AD26: =ROUND(IF(AC26="SI",V26*$AD$5,0),-3) -> 0 | AF26: =ROUND(IF(AE26="SI",V26*$AF$5,0),-3) -> 0 | AH26: =ROUND(IF(AG26="SI",V26*$AH$5,0),-3) -> 0 | AJ26: =IF(AI26="SI",V26*$AJ$5,0) -> 0 | AK26: =SUMIF('Otras Asesorías y Préstamos'!$B$7:$B$242,B26,'Otras Asesorías y Préstamos'!$F$7:$F$242) -> 0 | AL26: =SUMIF('Otras Asesorías y Préstamos'!$B$7:$B$242,B26,'Otras Asesorías y Préstamos'!$V$7:$V$242) -> 0 | AM26: =ROUND(SUM(V26:AK26),-4) -> 0
A27: =+A26+1 -> 19 | Q27: =+AL27 -> 0 | U27: SI | V27: =ROUND(IF(U27="SI",SUMIF('Facturas año anterior'!$B$8:$B$81,B27,'Facturas año anterior'!$V$8:$V$81)*(100%+$V$5),0),-3)+ROUND(IF(U27="SI",SUMIF('C de C año anterior'!$B$8:$B$210,B27,'C de C año anterior'!$Q$8:$Q$210)*(100%+$V$5),0),-3) -> 0 | X27: =ROUND(IF(W27="SI",V27*$X$5,0),-3) -> 0 | Z27: =ROUND(IF(Y27="SI",V27*$Z$5,0),-3) -> 0 | AB27: =ROUND(IF(AA27="SI",V27*$AB$5,0),-3) -> 0 | AD27: =ROUND(IF(AC27="SI",V27*$AD$5,0),-3) -> 0 | AF27: =ROUND(IF(AE27="SI",V27*$AF$5,0),-3) -> 0 | AH27: =ROUND(IF(AG27="SI",V27*$AH$5,0),-3) -> 0 | AJ27: =IF(AI27="SI",V27*$AJ$5,0) -> 0 | AK27: =SUMIF('Otras Asesorías y Préstamos'!$B$7:$B$242,B27,'Otras Asesorías y Préstamos'!$F$7:$F$242) -> 0 | AL27: =SUMIF('Otras Asesorías y Préstamos'!$B$7:$B$242,B27,'Otras Asesorías y Préstamos'!$V$7:$V$242) -> 0 | AM27: =ROUND(SUM(V27:AK27),-4) -> 0
A28: =+A27+1 -> 20 | Q28: =+AL28 -> 0 | U28: SI | V28: =ROUND(IF(U28="SI",SUMIF('Facturas año anterior'!$B$8:$B$81,B28,'Facturas año anterior'!$V$8:$V$81)*(100%+$V$5),0),-3)+ROUND(IF(U28="SI",SUMIF('C de C año anterior'!$B$8:$B$210,B28,'C de C año anterior'!$Q$8:$Q$210)*(100%+$V$5),0),-3) -> 0 | X28: =ROUND(IF(W28="SI",V28*$X$5,0),-3) -> 0 | Z28: =ROUND(IF(Y28="SI",V28*$Z$5,0),-3) -> 0 | AB28: =ROUND(IF(AA28="SI",V28*$AB$5,0),-3) -> 0 | AD28: =ROUND(IF(AC28="SI",V28*$AD$5,0),-3) -> 0 | AF28: =ROUND(IF(AE28="SI",V28*$AF$5,0),-3) -> 0 | AH28: =ROUND(IF(AG28="SI",V28*$AH$5,0),-3) -> 0 | AJ28: =IF(AI28="SI",V28*$AJ$5,0) -> 0 | AK28: =SUMIF('Otras Asesorías y Préstamos'!$B$7:$B$242,B28,'Otras Asesorías y Préstamos'!$F$7:$F$242) -> 0 | AL28: =SUMIF('Otras Asesorías y Préstamos'!$B$7:$B$242,B28,'Otras Asesorías y Préstamos'!$V$7:$V$242) -> 0 | AM28: =ROUND(SUM(V28:AK28),-4) -> 0
A29: =+A28+1 -> 21 | Q29: =+AL29 -> 0 | U29: SI | V29: =ROUND(IF(U29="SI",SUMIF('Facturas año anterior'!$B$8:$B$81,B29,'Facturas año anterior'!$V$8:$V$81)*(100%+$V$5),0),-3)+ROUND(IF(U29="SI",SUMIF('C de C año anterior'!$B$8:$B$210,B29,'C de C año anterior'!$Q$8:$Q$210)*(100%+$V$5),0),-3) -> 0 | X29: =ROUND(IF(W29="SI",V29*$X$5,0),-3) -> 0 | Y29: SI | Z29: =ROUND(IF(Y29="SI",V29*$Z$5,0),-3) -> 0 | AB29: =ROUND(IF(AA29="SI",V29*$AB$5,0),-3) -> 0 | AD29: =ROUND(IF(AC29="SI",V29*$AD$5,0),-3) -> 0 | AF29: =ROUND(IF(AE29="SI",V29*$AF$5,0),-3) -> 0 | AH29: =ROUND(IF(AG29="SI",V29*$AH$5,0),-3) -> 0 | AJ29: =IF(AI29="SI",V29*$AJ$5,0) -> 0 | AK29: =SUMIF('Otras Asesorías y Préstamos'!$B$7:$B$242,B29,'Otras Asesorías y Préstamos'!$F$7:$F$242) -> 0 | AL29: =SUMIF('Otras Asesorías y Préstamos'!$B$7:$B$242,B29,'Otras Asesorías y Préstamos'!$V$7:$V$242) -> 0 | AM29: =ROUND(SUM(V29:AK29),-4) -> 0
A30: =+A29+1 -> 22 | Q30: =+AL30 -> 0 | U30: SI | V30: =ROUND(IF(U30="SI",SUMIF('Facturas año anterior'!$B$8:$B$81,B30,'Facturas año anterior'!$V$8:$V$81)*(100%+$V$5),0),-3)+ROUND(IF(U30="SI",SUMIF('C de C año anterior'!$B$8:$B$210,B30,'C de C año anterior'!$Q$8:$Q$210)*(100%+$V$5),0),-3) -> 0 | X30: =ROUND(IF(W30="SI",V30*$X$5,0),-3) -> 0 | Z30: =ROUND(IF(Y30="SI",V30*$Z$5,0),-3) -> 0 | AB30: =ROUND(IF(AA30="SI",V30*$AB$5,0),-3) -> 0 | AD30: =ROUND(IF(AC30="SI",V30*$AD$5,0),-3) -> 0 | AF30: =ROUND(IF(AE30="SI",V30*$AF$5,0),-3) -> 0 | AH30: =ROUND(IF(AG30="SI",V30*$AH$5,0),-3) -> 0 | AI30: SI | AJ30: =IF(AI30="SI",V30*$AJ$5,0) -> 0 | AK30: =SUMIF('Otras Asesorías y Préstamos'!$B$7:$B$242,B30,'Otras Asesorías y Préstamos'!$F$7:$F$242) -> 0 | AL30: =SUMIF('Otras Asesorías y Préstamos'!$B$7:$B$242,B30,'Otras Asesorías y Préstamos'!$V$7:$V$242) -> 0 | AM30: =ROUND(SUM(V30:AK30),-4) -> 0
A31: =+A30+1 -> 23 | Q31: =+AL31 -> 0 | U31: SI | V31: =ROUND(IF(U31="SI",SUMIF('Facturas año anterior'!$B$8:$B$81,B31,'Facturas año anterior'!$V$8:$V$81)*(100%+$V$5),0),-3)+ROUND(IF(U31="SI",SUMIF('C de C año anterior'!$B$8:$B$210,B31,'C de C año anterior'!$Q$8:$Q$210)*(100%+$V$5),0),-3) -> 0 | X31: =ROUND(IF(W31="SI",V31*$X$5,0),-3) -> 0 | Z31: =ROUND(IF(Y31="SI",V31*$Z$5,0),-3) -> 0 | AB31: =ROUND(IF(AA31="SI",V31*$AB$5,0),-3) -> 0 | AD31: =ROUND(IF(AC31="SI",V31*$AD$5,0),-3) -> 0 | AF31: =ROUND(IF(AE31="SI",V31*$AF$5,0),-3) -> 0 | AH31: =ROUND(IF(AG31="SI",V31*$AH$5,0),-3) -> 0 | AJ31: =IF(AI31="SI",V31*$AJ$5,0) -> 0 | AK31: =SUMIF('Otras Asesorías y Préstamos'!$B$7:$B$242,B31,'Otras Asesorías y Préstamos'!$F$7:$F$242) -> 0 | AL31: =SUMIF('Otras Asesorías y Préstamos'!$B$7:$B$242,B31,'Otras Asesorías y Préstamos'!$V$7:$V$242) -> 0 | AM31: =ROUND(SUM(V31:AK31),-4) -> 0
A32: =+A31+1 -> 24 | Q32: =+AL32 -> 0 | U32: NO | V32: =ROUND(IF(U32="SI",SUMIF('Facturas año anterior'!$B$8:$B$81,B32,'Facturas año anterior'!$V$8:$V$81)*(100%+$V$5),0),-3)+ROUND(IF(U32="SI",SUMIF('C de C año anterior'!$B$8:$B$210,B32,'C de C año anterior'!$Q$8:$Q$210)*(100%+$V$5),0),-3) -> 0 | X32: =ROUND(IF(W32="SI",V32*$X$5,0),-3) -> 0 | Z32: =ROUND(IF(Y32="SI",V32*$Z$5,0),-3) -> 0 | AB32: =ROUND(IF(AA32="SI",V32*$AB$5,0),-3) -> 0 | AD32: =ROUND(IF(AC32="SI",V32*$AD$5,0),-3) -> 0 | AF32: =ROUND(IF(AE32="SI",V32*$AF$5,0),-3) -> 0 | AH32: =ROUND(IF(AG32="SI",V32*$AH$5,0),-3) -> 0 | AJ32: =IF(AI32="SI",V32*$AJ$5,0) -> 0 | AK32: =SUMIF('Otras Asesorías y Préstamos'!$B$7:$B$242,B32,'Otras Asesorías y Préstamos'!$F$7:$F$242) -> 0 | AL32: =SUMIF('Otras Asesorías y Préstamos'!$B$7:$B$242,B32,'Otras Asesorías y Préstamos'!$V$7:$V$242) -> 0 | AM32: =ROUND(SUM(V32:AK32),-4) -> 0
A33: =+A32+1 -> 25 | Q33: =+AL33 -> 0 | U33: SI | V33: =ROUND(IF(U33="SI",SUMIF('Facturas año anterior'!$B$8:$B$81,B33,'Facturas año anterior'!$V$8:$V$81)*(100%+$V$5),0),-3)+ROUND(IF(U33="SI",SUMIF('C de C año anterior'!$B$8:$B$210,B33,'C de C año anterior'!$Q$8:$Q$210)*(100%+$V$5),0),-3) -> 0 | X33: =ROUND(IF(W33="SI",V33*$X$5,0),-3) -> 0 | Z33: =ROUND(IF(Y33="SI",V33*$Z$5,0),-3) -> 0 | AB33: =ROUND(IF(AA33="SI",V33*$AB$5,0),-3) -> 0 | AD33: =ROUND(IF(AC33="SI",V33*$AD$5,0),-3) -> 0 | AF33: =ROUND(IF(AE33="SI",V33*$AF$5,0),-3) -> 0 | AH33: =ROUND(IF(AG33="SI",V33*$AH$5,0),-3) -> 0 | AJ33: =IF(AI33="SI",V33*$AJ$5,0) -> 0 | AK33: =SUMIF('Otras Asesorías y Préstamos'!$B$7:$B$242,B33,'Otras Asesorías y Préstamos'!$F$7:$F$242) -> 0 | AL33: =SUMIF('Otras Asesorías y Préstamos'!$B$7:$B$242,B33,'Otras Asesorías y Préstamos'!$V$7:$V$242) -> 0 | AM33: =ROUND(SUM(V33:AK33),-4) -> 0
A34: =+A33+1 -> 26 | U34: SI | V34: =ROUND(IF(U34="SI",SUMIF('Facturas año anterior'!$B$8:$B$81,B34,'Facturas año anterior'!$V$8:$V$81)*(100%+$V$5),0),-3)+ROUND(IF(U34="SI",SUMIF('C de C año anterior'!$B$8:$B$210,B34,'C de C año anterior'!$Q$8:$Q$210)*(100%+$V$5),0),-3) -> 0 | X34: =ROUND(IF(W34="SI",V34*$X$5,0),-3) -> 0 | Z34: =ROUND(IF(Y34="SI",V34*$Z$5,0),-3) -> 0 | AB34: =ROUND(IF(AA34="SI",V34*$AB$5,0),-3) -> 0 | AD34: =ROUND(IF(AC34="SI",V34*$AD$5,0),-3) -> 0 | AF34: =ROUND(IF(AE34="SI",V34*$AF$5,0),-3) -> 0 | AH34: =ROUND(IF(AG34="SI",V34*$AH$5,0),-3) -> 0 | AI34: SI | AJ34: =IF(AI34="SI",V34*$AJ$5,0) -> 0 | AK34: =SUMIF('Otras Asesorías y Préstamos'!$B$7:$B$242,B34,'Otras Asesorías y Préstamos'!$F$7:$F$242) -> 0 | AL34: =SUMIF('Otras Asesorías y Préstamos'!$B$7:$B$242,B34,'Otras Asesorías y Préstamos'!$V$7:$V$242) -> 0 | AM34: =ROUND(SUM(V34:AK34),-4) -> 0
A35: =+A34+1 -> 27 | Q35: =+AL35 -> 0 | U35: SI | V35: =ROUND(IF(U35="SI",SUMIF('Facturas año anterior'!$B$8:$B$81,B35,'Facturas año anterior'!$V$8:$V$81)*(100%+$V$5),0),-3)+ROUND(IF(U35="SI",SUMIF('C de C año anterior'!$B$8:$B$210,B35,'C de C año anterior'!$Q$8:$Q$210)*(100%+$V$5),0),-3) -> 0 | X35: =ROUND(IF(W35="SI",V35*$X$5,0),-3) -> 0 | Z35: =ROUND(IF(Y35="SI",V35*$Z$5,0),-3) -> 0 | AB35: =ROUND(IF(AA35="SI",V35*$AB$5,0),-3) -> 0 | AD35: =ROUND(IF(AC35="SI",V35*$AD$5,0),-3) -> 0 | AF35: =ROUND(IF(AE35="SI",V35*$AF$5,0),-3) -> 0 | AH35: =ROUND(IF(AG35="SI",V35*$AH$5,0),-3) -> 0 | AJ35: =IF(AI35="SI",V35*$AJ$5,0) -> 0 | AK35: =SUMIF('Otras Asesorías y Préstamos'!$B$7:$B$242,B35,'Otras Asesorías y Préstamos'!$F$7:$F$242) -> 0 | AL35: =SUMIF('Otras Asesorías y Préstamos'!$B$7:$B$242,B35,'Otras Asesorías y Préstamos'!$V$7:$V$242) -> 0 | AM35: =ROUND(SUM(V35:AK35),-4) -> 0
A36: =+A35+1 -> 28 | Q36: =+AL36 -> 0 | U36: SI | V36: =ROUND(IF(U36="SI",SUMIF('Facturas año anterior'!$B$8:$B$81,B36,'Facturas año anterior'!$V$8:$V$81)*(100%+$V$5),0),-3)+ROUND(IF(U36="SI",SUMIF('C de C año anterior'!$B$8:$B$210,B36,'C de C año anterior'!$Q$8:$Q$210)*(100%+$V$5),0),-3) -> 0 | X36: =ROUND(IF(W36="SI",V36*$X$5,0),-3) -> 0 | Z36: =ROUND(IF(Y36="SI",V36*$Z$5,0),-3) -> 0 | AB36: =ROUND(IF(AA36="SI",V36*$AB$5,0),-3) -> 0 | AD36: =ROUND(IF(AC36="SI",V36*$AD$5,0),-3) -> 0 | AF36: =ROUND(IF(AE36="SI",V36*$AF$5,0),-3) -> 0 | AH36: =ROUND(IF(AG36="SI",V36*$AH$5,0),-3) -> 0 | AJ36: =IF(AI36="SI",V36*$AJ$5,0) -> 0 | AK36: =SUMIF('Otras Asesorías y Préstamos'!$B$7:$B$242,B36,'Otras Asesorías y Préstamos'!$F$7:$F$242) -> 0 | AL36: =SUMIF('Otras Asesorías y Préstamos'!$B$7:$B$242,B36,'Otras Asesorías y Préstamos'!$V$7:$V$242) -> 0 | AM36: =ROUND(SUM(V36:AK36),-4) -> 0
A37: =+A36+1 -> 29 | Q37: =+AL37 -> 0 | U37: SI | V37: =ROUND(IF(U37="SI",SUMIF('Facturas año anterior'!$B$8:$B$81,B37,'Facturas año anterior'!$V$8:$V$81)*(100%+$V$5),0),-3)+ROUND(IF(U37="SI",SUMIF('C de C año anterior'!$B$8:$B$210,B37,'C de C año anterior'!$Q$8:$Q$210)*(100%+$V$5),0),-3) -> 0 | X37: =ROUND(IF(W37="SI",V37*$X$5,0),-3) -> 0 | Z37: =ROUND(IF(Y37="SI",V37*$Z$5,0),-3) -> 0 | AB37: =ROUND(IF(AA37="SI",V37*$AB$5,0),-3) -> 0 | AD37: =ROUND(IF(AC37="SI",V37*$AD$5,0),-3) -> 0 | AF37: =ROUND(IF(AE37="SI",V37*$AF$5,0),-3) -> 0 | AH37: =ROUND(IF(AG37="SI",V37*$AH$5,0),-3) -> 0 | AJ37: =IF(AI37="SI",V37*$AJ$5,0) -> 0 | AK37: =SUMIF('Otras Asesorías y Préstamos'!$B$7:$B$242,B37,'Otras Asesorías y Préstamos'!$F$7:$F$242) -> 0 | AL37: =SUMIF('Otras Asesorías y Préstamos'!$B$7:$B$242,B37,'Otras Asesorías y Préstamos'!$V$7:$V$242) -> 0 | AM37: =ROUND(SUM(V37:AK37),-4) -> 0
V38: =ROUND(IF(U38="SI",SUMIF('Facturas año anterior'!$B$8:$B$81,B38,'Facturas año anterior'!$V$8:$V$81)*(100%+$V$5),0),-3)+ROUND(IF(U38="SI",SUMIF('C de C año anterior'!$B$8:$B$210,B38,'C de C año anterior'!$F$8:$F$210)*(100%+$V$5),0),-3) -> 0 | X38: =ROUND(IF(W38="SI",V38*$X$5,0),-3) -> 0 | Z38: =ROUND(IF(Y38="SI",V38*$Z$5,0),-3) -> 0 | AB38: =ROUND(IF(AA38="SI",V38*$AB$5,0),-3) -> 0 | AD38: =ROUND(IF(AC38="SI",V38*$AD$5,0),-3) -> 0 | AF38: =ROUND(IF(AE38="SI",V38*$AF$5,0),-3) -> 0 | AH38: =ROUND(IF(AG38="SI",V38*$AH$5,0),-3) -> 0 | AJ38: =IF(AI38="SI",V38*$AJ$5,0) -> 0 | AK38: =SUMIF('Otras Asesorías y Préstamos'!$B$7:$B$242,B38,'Otras Asesorías y Préstamos'!$F$7:$F$242) -> 0 | AL38: =SUMIF('Otras Asesorías y Préstamos'!$B$7:$B$242,B38,'Otras Asesorías y Préstamos'!$V$7:$V$242) -> 0 | AM38: =ROUND(SUM(V38:AK38),-4) -> 0
V39: =ROUND(IF(U39="SI",SUMIF('Facturas año anterior'!$B$8:$B$81,B39,'Facturas año anterior'!$V$8:$V$81)*(100%+$V$5),0),-3)+ROUND(IF(U39="SI",SUMIF('C de C año anterior'!$B$8:$B$210,B39,'C de C año anterior'!$F$8:$F$210)*(100%+$V$5),0),-3) -> 0 | X39: =ROUND(IF(W39="SI",V39*$X$5,0),-3) -> 0 | Z39: =ROUND(IF(Y39="SI",V39*$Z$5,0),-3) -> 0 | AB39: =ROUND(IF(AA39="SI",V39*$AB$5,0),-3) -> 0 | AD39: =ROUND(IF(AC39="SI",V39*$AD$5,0),-3) -> 0 | AF39: =ROUND(IF(AE39="SI",V39*$AF$5,0),-3) -> 0 | AH39: =ROUND(IF(AG39="SI",V39*$AH$5,0),-3) -> 0 | AJ39: =IF(AI39="SI",V39*$AJ$5,0) -> 0 | AK39: =SUMIF('Otras Asesorías y Préstamos'!$B$7:$B$242,B39,'Otras Asesorías y Préstamos'!$F$7:$F$242) -> 0 | AL39: =SUMIF('Otras Asesorías y Préstamos'!$B$7:$B$242,B39,'Otras Asesorías y Préstamos'!$V$7:$V$242) -> 0 | AM39: =ROUND(SUM(V39:AK39),-4) -> 0
V40: =ROUND(IF(U40="SI",SUMIF('Facturas año anterior'!$B$8:$B$81,B40,'Facturas año anterior'!$V$8:$V$81)*(100%+$V$5),0),-3)+ROUND(IF(U40="SI",SUMIF('C de C año anterior'!$B$8:$B$210,B40,'C de C año anterior'!$F$8:$F$210)*(100%+$V$5),0),-3) -> 0 | X40: =ROUND(IF(W40="SI",V40*$X$5,0),-3) -> 0 | Z40: =ROUND(IF(Y40="SI",V40*$Z$5,0),-3) -> 0 | AB40: =ROUND(IF(AA40="SI",V40*$AB$5,0),-3) -> 0 | AD40: =ROUND(IF(AC40="SI",V40*$AD$5,0),-3) -> 0 | AF40: =ROUND(IF(AE40="SI",V40*$AF$5,0),-3) -> 0 | AH40: =ROUND(IF(AG40="SI",V40*$AH$5,0),-3) -> 0 | AJ40: =IF(AI40="SI",V40*$AJ$5,0) -> 0 | AK40: =SUMIF('Otras Asesorías y Préstamos'!$B$7:$B$242,B40,'Otras Asesorías y Préstamos'!$F$7:$F$242) -> 0 | AL40: =SUMIF('Otras Asesorías y Préstamos'!$B$7:$B$242,B40,'Otras Asesorías y Préstamos'!$V$7:$V$242) -> 0 | AM40: =ROUND(SUM(V40:AK40),-4) -> 0
V41: =ROUND(IF(U41="SI",SUMIF('Facturas año anterior'!$B$8:$B$81,B41,'Facturas año anterior'!$V$8:$V$81)*(100%+$V$5),0),-3)+ROUND(IF(U41="SI",SUMIF('C de C año anterior'!$B$8:$B$210,B41,'C de C año anterior'!$F$8:$F$210)*(100%+$V$5),0),-3) -> 0 | X41: =ROUND(IF(W41="SI",V41*$X$5,0),-3) -> 0 | Z41: =ROUND(IF(Y41="SI",V41*$Z$5,0),-3) -> 0 | AB41: =ROUND(IF(AA41="SI",V41*$AB$5,0),-3) -> 0 | AD41: =ROUND(IF(AC41="SI",V41*$AD$5,0),-3) -> 0 | AF41: =ROUND(IF(AE41="SI",V41*$AF$5,0),-3) -> 0 | AH41: =ROUND(IF(AG41="SI",V41*$AH$5,0),-3) -> 0 | AJ41: =IF(AI41="SI",V41*$AJ$5,0) -> 0 | AK41: =SUMIF('Otras Asesorías y Préstamos'!$B$7:$B$242,B41,'Otras Asesorías y Préstamos'!$F$7:$F$242) -> 0 | AL41: =SUMIF('Otras Asesorías y Préstamos'!$B$7:$B$242,B41,'Otras Asesorías y Préstamos'!$V$7:$V$242) -> 0 | AM41: =ROUND(SUM(V41:AK41),-4) -> 0
V42: =ROUND(IF(U42="SI",SUMIF('Facturas año anterior'!$B$8:$B$81,B42,'Facturas año anterior'!$V$8:$V$81)*(100%+$V$5),0),-3)+ROUND(IF(U42="SI",SUMIF('C de C año anterior'!$B$8:$B$210,B42,'C de C año anterior'!$F$8:$F$210)*(100%+$V$5),0),-3) -> 0 | X42: =ROUND(IF(W42="SI",V42*$X$5,0),-3) -> 0 | Z42: =ROUND(IF(Y42="SI",V42*$Z$5,0),-3) -> 0 | AB42: =ROUND(IF(AA42="SI",V42*$AB$5,0),-3) -> 0 | AD42: =ROUND(IF(AC42="SI",V42*$AD$5,0),-3) -> 0 | AF42: =ROUND(IF(AE42="SI",V42*$AF$5,0),-3) -> 0 | AH42: =ROUND(IF(AG42="SI",V42*$AH$5,0),-3) -> 0 | AJ42: =IF(AI42="SI",V42*$AJ$5,0) -> 0 | AK42: =SUMIF('Otras Asesorías y Préstamos'!$B$7:$B$242,B42,'Otras Asesorías y Préstamos'!$F$7:$F$242) -> 0 | AL42: =SUMIF('Otras Asesorías y Préstamos'!$B$7:$B$242,B42,'Otras Asesorías y Préstamos'!$V$7:$V$242) -> 0 | AM42: =ROUND(SUM(V42:AK42),-4) -> 0
...

Sheet Cuentas de Cobro
A1: =+'Grupos Familiares'!$A$1 -> 0
A2: =+'Grupos Familiares'!$A$3 -> PRESUPUESTO DE COBROS | M2: Mínima Mvto | N2: Mínima 1° Vez | P2: PARA CALCULAR EL VALOR A COBRAR POR EL PRESENTE AÑO
A3: CUENTAS DE COBRO | D3: 42684082 | M3: =(+Facturas!Q3) -> 230000 | N3: =+Facturas!S3 -> 370000
A4: =+'Grupos Familiares'!$A$4 -> AÑO GRAVABLE 2024 | F4: VALORES CUENTAS DE COBRO 2023 | P4: PRESUPUESTOS DE COBRO: | T4: =+$A$3 -> CUENTAS DE COBRO
A5: PERSONAS NATURALES Y PERSONAS JURÍDICAS | P5: IPC | Q5: =+Facturas!V5 -> 0.052 | S5: 0.5 | U5: =75%+80%*0 -> 0.75 | W5: 0.15 | Y5: 0.2 | AA5: 0.1 | AC5: 0.2 | AE5: 0.3
A6: No. | B6: APELLIDOS Y NOMBRES o RAZÓN SOCIAL | C6: CÓDIGO | D6: NIT No. | E6: D. V. | F6: VALOR A ELABORAR LA CUENTA DE COBRO | G6: CUENTA DE COBRO No. | H6: ENVIADA | I6: FECHA ENVIO | J6: ESTADO DEL COBRO | K6: MEDIO DE PAGO | L6: FECHA DE PAGO | M6: OBSERVACIONES-1 | N6: OBSERVACIONES-2 | P6: SI o NO | Q6: VALOR DECLARACIÓN RENTA | R6: SI o NO | S6: VALOR DECLARACIÓN I AL P | T6: SI o NO | U6: VALOR MEDIOS MAGNÉTICOS | V6: SI o NO | W6: EXÓGENA MPIO MEDELLÍN | X6: SI o NO | Y6: REG ÚNICO de BENEFICIARIOS | Z6: SI o NO | AA6: VALOR FORMATO 2516 CONSERVAR | AB6: SI o NO | AC6: VALOR FORMATO 2516 TRANSMITIR | AD6: SI o NO | AE6: VALOR DECLARACIÓN ACTIVOS EN EL EXTERIOR | AF6: VALOR ASESORÍAS | AG6: VALOR PRÉSTAMOS | AH6: TOTAL PRESUPUESTADO
A8: PERSONAS NATURALES
A9: 1 | B9: NOMBRE 1 | C9: =_xlfn.XLOOKUP(B9,Códigos!$B$8:$B$406,Códigos!$A$8:$A$406,"Verificar",0) -> 41 | D9: =_xlfn.XLOOKUP(B9,'Consolidado Cobros'!$B$10:$B$268,'Consolidado Cobros'!$C$10:$C$268,"Verificar",0) -> 22126399 | E9: =IF((MOD((VALUE(MID(TEXT(D9,"000000000000000"),15,1))*3+VALUE(MID(TEXT(D9,"000000000000000"),14,1))*7+VALUE(MID(TEXT(D9,"000000000000000"),13,1))*13+VALUE(MID(TEXT(D9,"000000000000000"),12,1))*17+VALUE(MID(TEXT(D9,"000000000000000"),11,1))*19+VALUE(MID(TEXT(D9,"000000000000000"),10,1))*23+VALUE(MID(TEXT(D9,"000000000000000"),9,1))*29+VALUE(MID(TEXT(D9,"000000000000000"),8,1))*37+VALUE(MID(TEXT(D9,"000000000000000"),7,1))*41+VALUE(MID(TEXT(D9,"000000000000000"),6,1))*43+VALUE(MID(TEXT(D9,"000000000000000"),5,1))*47+VALUE(MID(TEXT(D9,"000000000000000"),4,1))*53+VALUE(MID(TEXT(D9,"000000000000000"),3,1))*59+VALUE(MID(TEXT(D9,"000000000000000"),2,1))*67+VALUE(MID(TEXT(D9,"000000000000000"),1,1))*71),11))=0,0,IF((MOD((VALUE(MID(TEXT(D9,"000000000000000"),15,1))*3+VALUE(MID(TEXT(D9,"000000000000000"),14,1))*7+VALUE(MID(TEXT(D9,"000000000000000"),13,1))*13+VALUE(MID(TEXT(D9,"000000000000000"),12,1))*17+VALUE(MID(TEXT(D9,"000000000000000"),11,1))*19+VALUE(MID(TEXT(D9,"000000000000000"),10,1))*23+VALUE(MID(TEXT(D9,"000000000000000"),9,1))*29+VALUE(MID(TEXT(D9,"000000000000000"),8,1))*37+VALUE(MID(TEXT(D9,"000000000000000"),7,1))*41+VALUE(MID(TEXT(D9,"000000000000000"),6,1))*43+VALUE(MID(TEXT(D9,"000000000000000"),5,1))*47+VALUE(MID(TEXT(D9,"000000000000000"),4,1))*53+VALUE(MID(TEXT(D9,"000000000000000"),3,1))*59+VALUE(MID(TEXT(D9,"000000000000000"),2,1))*67+VALUE(MID(TEXT(D9,"000000000000000"),1,1))*71),11))=1,1,11-(MOD((VALUE(MID(TEXT(D9,"000000000000000"),15,1))*3+VALUE(MID(TEXT(D9,"000000000000000"),14,1))*7+VALUE(MID(TEXT(D9,"000000000000000"),13,1))*13+VALUE(MID(TEXT(D9,"000000000000000"),12,1))*17+VALUE(MID(TEXT(D9,"000000000000000"),11,1))*19+VALUE(MID(TEXT(D9,"000000000000000"),10,1))*23+VALUE(MID(TEXT(D9,"000000000000000"),9,1))*29+VALUE(MID(TEXT(D9,"000000000000000"),8,1))*37+VALUE(MID(TEXT(D9,"000000000000000"),7,1))*41+VALUE(MID(TEXT(D9,"000000000000000"),6,1))*43+VALUE(MID(TEXT(D9,"000000000000000"),5,1))*47+VALUE(MID(TEXT(D9,"000000000000000"),4,1))*53+VALUE(MID(TEXT(D9,"000000000000000"),3,1))*59+VALUE(MID(TEXT(D9,"000000000000000"),2,1))*67+VALUE(MID(TEXT(D9,"000000000000000"),1,1))*71),11)))) -> 5 | F9: =+AH9 -> 900000 | G9: 25-118 | P9: SI | Q9: =ROUND(IF(P9="SI",SUMIF('C de C año anterior'!$B$8:$B$229,B9,'C de C año anterior'!$Q$8:$Q$229)*(100%+$Q$5),0),-3)+ROUND(IF(P9="SI",SUMIF('Facturas año anterior'!$B$8:$B$86,B9,'Facturas año anterior'!$V$8:$V$86)*(100%+$AA$5),0),-3) -> 895000 | S9: =ROUND(IF(R9="SI",Q9*$S$5,0),-3) -> 0 | U9: =ROUND(IF(T9="SI",Q9*$U$5,0),-3) -> 0 | W9: =ROUND(IF(V9="SI",Q9*$W$5,0),-3) -> 0 | Y9: =ROUND(IF(X9="SI",Q9*$Y$5,0),-3) -> 0 | AA9: =ROUND(IF(Z9="SI",Q9*$AA$5,0),-3) -> 0 | AC9: =ROUND(IF(AB9="SI",Q9*$AC$5,0),-3) -> 0 | AE9: =IF(AD9="SI",Q9*$AE$5,0) -> 0 | AF9: =SUMIF('Otras Asesorías y Préstamos'!$B$7:$B$242,B9,'Otras Asesorías y Préstamos'!$F$7:$F$242) -> 0 | AG9: =SUMIF('Otras Asesorías y Préstamos'!$B$7:$B$242,B9,'Otras Asesorías y Préstamos'!$V$7:$V$242) -> 0 | AH9: =ROUND(SUM(Q9:AG9),-4) -> 900000
